Workbook

Sheet 0. Budget Summary
A1: 0. Budget Summary (다음 Sheet 입력 시 자동 생성)
A3: Protocol No: TTK-CS-101 | E3: Updated on:
A5: 1. Overall Status
B6: IQVIA | C6: Syneos | D6: Sharp | E6: Fisher | F6: Marken | G6: SBQ | H6: Aptamer | I6: Invivo | J6: Labconnect | K6: AIMS
B7: CRO CO | C7: Previous CRO CO 현 DMSTAT/PV: 예산은 CD팀에서 관리 | D7: Packaging, Delivery, Destruction, etc | E7: Packaging, Delivery, Destruction, etc | F7: IP Transpotation | G7: PK, SS1 & SS3 | H7: PK, SS2 & SS4 | I7: Biomarker, SS4 | J7: Lab Kit, SS4 | K7: Consulting
A8: Contracted | B8: ='[1]1. IQVIA '!B8 -> 15935420 | D8: ='[1]3. Sharp'!B8 -> 675051 | E8: ='[1]4. Fisher'!B8 -> 249693702 | F8: ='[1]5. Marken'!B8 -> 132368849 | G8: ='6. SBQ'!B8 -> 440404.83 | H8: ='7. Aptamer'!B8 -> 294600000 | I8: ='8. Invivo'!B8 -> 490894 | J8: ='9. Labconnect'!B8 -> 68277 | K8: ='10. AIMS'!B8 -> 367130000
A9: Paid | B9: ='[1]1. IQVIA '!B9 -> 3144815.9 | C9: ='2. Syneos'!B9 -> 0 | D9: ='[1]3. Sharp'!B9 -> 472838.16 | E9: ='[1]4. Fisher'!B9 -> 15142569 | F9: ='[1]5. Marken'!B9 -> 132368849 | G9: ='6. SBQ'!B9 -> 160795.18 | H9: ='7. Aptamer'!B9 -> 54450000 | I9: ='8. Invivo'!B9 -> 213142.36 | J9: ='9. Labconnect'!B9 -> 45962.23 | K9: ='10. AIMS'!B9 -> 250597600
A10: Remaining | B10: ='[1]1. IQVIA '!B10 -> 12790605 | D10: ='[1]3. Sharp'!B10 -> 202212.84 | E10: ='[1]4. Fisher'!B10 -> 234551133 | F10: ='[1]5. Marken'!B10 -> 0 | G10: ='6. SBQ'!B10 -> 279609.65 | H10: ='7. Aptamer'!B10 -> 240150000 | I10: ='8. Invivo'!B10 -> 277751.64 | J10: ='9. Labconnect'!B10 -> 22314.77 | K10: ='10. AIMS'!B10 -> 116532400
A11: % | B11: ='[1]1. IQVIA '!C10 -> 0.80265247 | D11: ='[1]3. Sharp'!C10 -> 0.29955194 | E11: ='[1]4. Fisher'!C10 -> 0.93935542 | F11: ='[1]5. Marken'!C10 -> 0 | G11: ='6. SBQ'!C10 -> 0.63489233 | H11: ='7. Aptamer'!C10 -> 0.81517312 | I11: ='8. Invivo'!C10 -> 0.56580777 | J11: ='9. Labconnect'!C10 -> 0.32682704 | K11: ='10. AIMS'!C10 -> 0.31741454
A13: 2. Yearly/Quarterly Plan and Payment Status
A14: Vendor | B14: Currency | C14: 2023 | N14: 2024 | Y14: 2025 | AJ14: 2026 | AU14: 2027
C15: 1Q (Jan~Mar) | E15: 2Q (Apr~Jun) | G15: 3Q (Jul~Sep) | I15: 4Q (Oct~Dec) | K15: 2023 | N15: 1Q (Jan~Mar) | P15: 2Q (Apr~Jun) | R15: 3Q (Jul~Sep) | T15: 4Q (Oct~Dec) | V15: 2024 | Y15: 1Q (Jan~Mar) | AA15: 2Q (Apr~Jun) | AC15: 3Q (Jul~Sep) | AE15: 4Q (Oct~Dec) | AG15: 2025 | AJ15: 1Q (Jan~Mar) | AL15: 2Q (Apr~Jun) | AN15: 3Q (Jul~Sep) | AP15: 4Q (Oct~Dec) | AR15: 2026 | AU15: 1Q (Jan~Mar) | AW15: 2Q (Apr~Jun) | AY15: 3Q (Jul~Sep) | BA15: 4Q (Oct~Dec) | BC15: 2027
C16: Planned | D16: Actual | E16: Planned | F16: Actual | G16: Planned | H16: Actual | I16: Planned | J16: Actual | K16: Planned | L16: Actual | M16: Delta (Δ) | N16: Planned | O16: Actual | P16: Planned | Q16: Actual | R16: Planned | S16: Actual | T16: Planned | U16: Actual | V16: Planned | W16: Actual | X16: Delta (Δ) | Y16: Planned | Z16: Actual | AA16: Planned | AB16: Actual | AC16: Planned | AD16: Actual | AE16: Planned | AF16: Actual | AG16: Planned | AH16: Actual | AI16: Delta (Δ) | AJ16: Planned | AK16: Actual | AL16: Planned | AM16: Actual | AN16: Planned | AO16: Actual | AP16: Planned | AQ16: Actual | AR16: Planned | AS16: Actual | AT16: Delta (Δ) | AU16: Planned | AV16: Actual | AW16: Planned | AX16: Actual | AY16: Planned | AZ16: Actual | BA16: Planned | BB16: Actual | BC16: Planned | BD16: Actual | BE16: Delta (Δ)
A17: CRO(IQVIA) | B17: USD | K17: =C17+E17+G17+I17 -> 0 | L17: =D17+F17+H17+J17 -> 0 | M17: =K17-L17 -> 0 | O17: ='1. IQVIA '!A16+'1. IQVIA '!B16+'1. IQVIA '!C16 -> 0 | Q17: ='1. IQVIA '!D16+'1. IQVIA '!E16+'1. IQVIA '!F16 -> 0 | S17: ='1. IQVIA '!G16+'1. IQVIA '!H16+'1. IQVIA '!I16 -> 297156.95 | U17: ='1. IQVIA '!J16+'1. IQVIA '!K16+'1. IQVIA '!L16 -> 2772764 | V17: =N17+P17+R17+T17 -> 0 | W17: =O17+Q17+S17+U17 -> 3069920.9 | X17: =V17-W17 -> -3069920.9 | Z17: ='1. IQVIA '!A21+'1. IQVIA '!B21+'1. IQVIA '!C21 -> 34695.35 | AB17: ='1. IQVIA '!D21+'1. IQVIA '!E21+'1. IQVIA '!F21 -> 656709.24 | AD17: ='1. IQVIA '!G21+'1. IQVIA '!H21+'1. IQVIA '!I21 -> 829858.16 | AE17: 772849 | AF17: ='1. IQVIA '!J21+'1. IQVIA '!K21+'1. IQVIA '!L21 -> 2380983.1 | AG17: =Y17+AA17+AC17+AE17 -> 772849 | AH17: =Z17+AB17+AD17+AF17 -> 3902245.9 | AI17: =AG17-AH17 -> -3129396.9 | AJ17: 1050743 | AK17: ='1. IQVIA '!A26+'1. IQVIA '!B26+'1. IQVIA '!C26 -> 1305306.7 | AL17: 437810 | AM17: ='1. IQVIA '!D26+'1. IQVIA '!E26+'1. IQVIA '!F26 -> 1431538.8 | AN17: 437810 | AO17: ='1. IQVIA '!G26+'1. IQVIA '!H26+'1. IQVIA '!I26 -> 134077.92 | AP17: 350243 | AQ17: ='1. IQVIA '!J26+'1. IQVIA '!K26+'1. IQVIA '!L26 -> 0 | AR17: =AJ17+AL17+AN17+AP17 -> 2276606 | AS17: =AK17+AM17+AO17+AQ17 -> 2870923.4 | AT17: =AR17-AS17 -> -594317.44 | AU17: 350243 | AV17: ='1. IQVIA '!A31+'1. IQVIA '!B31+'1. IQVIA '!C31 -> 0 | AW17: 262686 | AX17: ='1. IQVIA '!D31+'1. IQVIA '!E31+'1. IQVIA '!F31 -> 0 | AZ17: ='1. IQVIA '!G31+'1. IQVIA '!H31+'1. IQVIA '!I31 -> 0 | BB17: ='1. IQVIA '!J31+'1. IQVIA '!K31+'1. IQVIA '!L31 -> 0 | BC17: =AU17+AW17+AY17+BA17 -> 612929 | BD17: =AV17+AX17+AZ17+BB17 -> 0 | BE17: =BC17-BD17 -> 612929
A18: CRO(Syneos) | B18: USD | D18: ='2. Syneos'!A16+'2. Syneos'!B16+'2. Syneos'!C16 -> 0 | F18: ='2. Syneos'!D16+'2. Syneos'!E16+'2. Syneos'!F16 -> 0 | H18: ='2. Syneos'!G16+'2. Syneos'!H16+'2. Syneos'!I16 -> 0 | J18: ='2. Syneos'!J16+'2. Syneos'!K16+'2. Syneos'!L16 -> 0 | K18: =C18+E18+G18+I18 -> 0 | L18: =D18+F18+H18+J18 -> 0 | M18: =K18-L18 -> 0 | O18: ='2. Syneos'!A21+'2. Syneos'!B21+'2. Syneos'!C21 -> 0 | Q18: ='2. Syneos'!D21+'2. Syneos'!E21+'2. Syneos'!F21 -> 0 | S18: ='2. Syneos'!G21+'2. Syneos'!H21+'2. Syneos'!I21 -> 0 | U18: ='2. Syneos'!J21+'2. Syneos'!K21+'2. Syneos'!L21 -> 0 | V18: =N18+P18+R18+T18 -> 0 | W18: =O18+Q18+S18+U18 -> 0 | X18: =V18-W18 -> 0 | Z18: ='2. Syneos'!A26+'2. Syneos'!B26+'2. Syneos'!C26 -> 0 | AB18: ='2. Syneos'!D26+'2. Syneos'!E26+'2. Syneos'!F26 -> 0 | AD18: ='2. Syneos'!G26+'2. Syneos'!H26+'2. Syneos'!I26 -> 0 | AE18: 364505 | AF18: ='2. Syneos'!J26+'2. Syneos'!K26+'2. Syneos'!L26 -> 0 | AG18: =Y18+AA18+AC18+AE18 -> 364505 | AH18: =Z18+AB18+AD18+AF18 -> 0 | AI18: =AG18-AH18 -> 364505 | AJ18: 543464 | AK18: ='2. Syneos'!A31+'2. Syneos'!B31+'2. Syneos'!C31 -> 0 | AL18: 452886 | AM18: ='2. Syneos'!D31+'2. Syneos'!E31+'2. Syneos'!F31 -> 0 | AN18: 377405 | AO18: ='2. Syneos'!G31+'2. Syneos'!H31+'2. Syneos'!I31 -> 0 | AP18: 314504 | AQ18: ='2. Syneos'!J31+'2. Syneos'!K31+'2. Syneos'!L31 -> 0 | AR18: =AJ18+AL18+AN18+AP18 -> 1688259 | AS18: =AK18+AM18+AO18+AQ18 -> 0 | AT18: =AR18-AS18 -> 1688259 | AU18: 262087 | AV18: ='2. Syneos'!A36+'2. Syneos'!B36+'2. Syneos'!C36 -> 0 | AX18: ='2. Syneos'!D36+'2. Syneos'!E36+'2. Syneos'!F36 -> 0 | AY18: 262087 | AZ18: ='2. Syneos'!G36+'2. Syneos'!H36+'2. Syneos'!I36 -> 0 | BB18: ='2. Syneos'!J36+'2. Syneos'!K36+'2. Syneos'!L36 -> 0 | BC18: =AU18+AY18+BA18 -> 524174 | BD18: =AV18+AX18+AZ18+BB18 -> 0 | BE18: =BC18-BD18 -> 524174
A19: Sharp | B19: USD | D19: ='[1]3. Sharp'!A15+'[1]3. Sharp'!B15+'[1]3. Sharp'!C15 -> 12267 | F19: ='[1]3. Sharp'!D15+'[1]3. Sharp'!E15+'[1]3. Sharp'!F15 -> 16333.47 | H19: ='[1]3. Sharp'!G15+'[1]3. Sharp'!H15+'[1]3. Sharp'!I15 -> 46052.33 | J19: ='[1]3. Sharp'!J15+'[1]3. Sharp'!K15+'[1]3. Sharp'!L15 -> 20282.86 | K19: =C19+E19+G19+I19 -> 0 | L19: =D19+F19+H19+J19 -> 94935.66 | M19: =K19-L19 -> -94935.66 | O19: ='[1]3. Sharp'!A20+'[1]3. Sharp'!B20+'[1]3. Sharp'!C20 -> 7522.83 | Q19: ='[1]3. Sharp'!D20+'[1]3. Sharp'!E20+'[1]3. Sharp'!F20 -> 49874.57 | S19: ='[1]3. Sharp'!G20+'[1]3. Sharp'!H20+'[1]3. Sharp'!I20 -> 41664.66 | U19: ='[1]3. Sharp'!J20+'[1]3. Sharp'!K20+'[1]3. Sharp'!L20 -> 31336.49 | V19: =N19+P19+R19+T19 -> 0 | W19: =O19+Q19+S19+U19 -> 130398.55 | X19: =V19-W19 -> -130398.55 | Z19: ='[1]3. Sharp'!A25+'[1]3. Sharp'!B25+'[1]3. Sharp'!C25 -> 25424.65 | AB19: ='[1]3. Sharp'!D25+'[1]3. Sharp'!E25+'[1]3. Sharp'!F25 -> 68361.41 | AD19: ='[1]3. Sharp'!G25+'[1]3. Sharp'!H25+'[1]3. Sharp'!I25 -> 100122.42 | AF19: ='[1]3. Sharp'!J25+'[1]3. Sharp'!K25+'[1]3. Sharp'!L25 -> 53595.47 | AG19: =Y19+AA19+AC19+AE19 -> 0 | AH19: =Z19+AB19+AD19+AF19 -> 247503.95 | AI19: =AG19-AH19 -> -247503.95 | AK19: ='[1]3. Sharp'!A30+'[1]3. Sharp'!B30+'[1]3. Sharp'!C30 -> 0 | AM19: ='[1]3. Sharp'!D30+'[1]3. Sharp'!E30+'[1]3. Sharp'!F30 -> 0 | AO19: ='[1]3. Sharp'!G30+'[1]3. Sharp'!H30+'[1]3. Sharp'!I30 -> 0 | AQ19: ='[1]3. Sharp'!J30+'[1]3. Sharp'!K30+'[1]3. Sharp'!L30 -> 0 | AR19: =AJ19+AL19+AN19+AP19 -> 0 | AS19: =AK19+AM19+AO19+AQ19 -> 0 | AT19: =AR19-AS19 -> 0 | AV19: ='[1]3. Sharp'!A35+'[1]3. Sharp'!B35+'[1]3. Sharp'!C35 -> 0 | AX19: ='[1]3. Sharp'!D35+'[1]3. Sharp'!E35+'[1]3. Sharp'!F35 -> 0 | AZ19: ='[1]3. Sharp'!G35+'[1]3. Sharp'!H35+'[1]3. Sharp'!I35 -> 0 | BB19: ='[1]3. Sharp'!J35+'[1]3. Sharp'!K35+'[1]3. Sharp'!L35 -> 0 | BC19: =AU19+AW18+AY19+BA19 -> 0 | BD19: =AV19+AX19+AZ19+BB19 -> 0 | BE19: =BC19-BD19 -> 0
A20: Fisher | B20: KRW | K20: =C20+E20+G20+I20 -> 0 | L20: =D20+F20+H20+J20 -> 0 | M20: =K20-L20 -> 0 | V20: =N20+P20+R20+T20 -> 0 | W20: =O20+Q20+S20+U20 -> 0 | X20: =V20-W20 -> 0 | Z20: ='[1]4. Fisher'!A17+'[1]4. Fisher'!B17+'[1]4. Fisher'!C17 -> 0 | AB20: ='[1]4. Fisher'!D17+'[1]4. Fisher'!E17+'[1]4. Fisher'!F17 -> 0 | AD20: ='[1]4. Fisher'!G17+'[1]4. Fisher'!H17+'[1]4. Fisher'!I17 -> 4838959 | AF20: ='[1]4. Fisher'!J17+'[1]4. Fisher'!K17+'[1]4. Fisher'!L17 -> 10303610 | AG20: =Y20+AA20+AC20 -> 0 | AH20: =Z20+AB20+AD20 -> 4838959 | AI20: =AG20-AH20 -> -4838959 | AK20: ='[1]4. Fisher'!A22+'[1]4. Fisher'!B22+'[1]4. Fisher'!C22 -> 0 | AM20: ='[1]4. Fisher'!D22+'[1]4. Fisher'!E22+'[1]4. Fisher'!F22 -> 0 | AO20: ='[1]4. Fisher'!G22+'[1]4. Fisher'!H22+'[1]4. Fisher'!I22 -> 0 | AQ20: ='[1]4. Fisher'!J22+'[1]4. Fisher'!K22+'[1]4. Fisher'!L22 -> 0 | AR20: =AJ20+AL20+AN20 -> 0 | AS20: =AK20+AM20+AO20 -> 0 | AT20: =AR20-AS20 -> 0 | AV20: ='[1]4. Fisher'!A27+'[1]4. Fisher'!B27+'[1]4. Fisher'!C27 -> 0 | AX20: ='[1]4. Fisher'!D27+'[1]4. Fisher'!E27+'[1]4. Fisher'!F27 -> 0 | AZ20: ='[1]4. Fisher'!G27+'[1]4. Fisher'!H27+'[1]4. Fisher'!I27 -> 0 | BB20: ='[1]4. Fisher'!J27+'[1]4. Fisher'!K27+'[1]4. Fisher'!L27 -> 0 | BC20: =AU20+AW20+AY20 -> 0 | BD20: =AV20+AX20+AZ20 -> 0 | BE20: =BC20-BD20 -> 0
A21: Marken | B21: KRW | D21: ='[1]5. Marken'!A17+'[1]5. Marken'!B17+'[1]5. Marken'!C17 -> 0 | F21: ='[1]5. Marken'!D17+'[1]5. Marken'!E17+'[1]5. Marken'!F17 -> 6832940 | H21: ='[1]5. Marken'!G17+'[1]5. Marken'!H17+'[1]5. Marken'!I17 -> 42000 | J21: ='[1]5. Marken'!J17+'[1]5. Marken'!K17+'[1]5. Marken'!L17 -> 0 | K21: =C21+E21+G21+I21 -> 0 | L21: =D21+F21+H21+J21 -> 6874940 | M21: =K21-L21 -> -6874940 | O21: ='[1]5. Marken'!A22+'[1]5. Marken'!B22+'[1]5. Marken'!C22 -> 0 | Q21: ='[1]5. Marken'!D22+'[1]5. Marken'!E22+'[1]5. Marken'!F22 -> 29201942 | S21: ='[1]5. Marken'!G22+'[1]5. Marken'!H22+'[1]5. Marken'!I22 -> 0 | U21: ='[1]5. Marken'!J22+'[1]5. Marken'!K22+'[1]5. Marken'!L22 -> 10670790 | V21: =N21+P21+R21+T21 -> 0 | W21: =O21+Q21+S21+U21 -> 39872732 | X21: =V21-W21 -> -39872732 | Z21: ='[1]5. Marken'!A27+'[1]5. Marken'!B27+'[1]5. Marken'!C27 -> 0 | AB21: ='[1]5. Marken'!D27+'[1]5. Marken'!E27+'[1]5. Marken'!F27 -> 2942881 | AD21: ='[1]5. Marken'!G27+'[1]5. Marken'!H27+'[1]5. Marken'!I27 -> 39794243 | AF21: ='[1]5. Marken'!J27+'[1]5. Marken'!K27+'[1]5. Marken'!L27 -> 42884053 | AG21: =Y21+AA21+AC21+AE21 -> 0 | AH21: =Z21+AB21+AD21+AF21 -> 85621177 | AI21: =AG21-AH21 -> -85621177 | AK21: ='[1]5. Marken'!A32+'[1]5. Marken'!B32+'[1]5. Marken'!C32 -> 0 | AM21: ='[1]5. Marken'!D32+'[1]5. Marken'!E32+'[1]5. Marken'!F32 -> 0 | AO21: ='[1]5. Marken'!G32+'[1]5. Marken'!H32+'[1]5. Marken'!I32 -> 0 | AQ21: ='[1]5. Marken'!J32+'[1]5. Marken'!K32+'[1]5. Marken'!L32 -> 0 | AR21: =AJ21+AL21+AN21+AP21 -> 0 | AS21: =AK21+AM21+AO21+AQ21 -> 0 | AT21: =AR21-AS21 -> 0 | AV21: ='[1]5. Marken'!A37+'[1]5. Marken'!B37+'[1]5. Marken'!C37 -> 0 | AX21: ='[1]5. Marken'!D37+'[1]5. Marken'!E37+'[1]5. Marken'!F37 -> 0 | AZ21: ='[1]5. Marken'!G37+'[1]5. Marken'!H37+'[1]5. Marken'!I37 -> 0 | BB21: ='[1]5. Marken'!J37+'[1]5. Marken'!K37+'[1]5. Marken'!L37 -> 0 | BC21: =AU21+AW21+AY21+BA21 -> 0 | BD21: =AV21+AX21+AZ21+BB21 -> 0 | BE21: =BC21-BD21 -> 0
A22: SBQ | B22: CHF | D22: ='6. SBQ'!A16+'6. SBQ'!B16+'6. SBQ'!C16 -> 67333.98 | F22: ='6. SBQ'!D16+'6. SBQ'!E16+'6. SBQ'!F16 -> 0 | H22: ='6. SBQ'!G16+'6. SBQ'!H16+'6. SBQ'!I16 -> 1968 | J22: ='6. SBQ'!J16+'6. SBQ'!K16+'6. SBQ'!L16 -> 0 | K22: =C22+E22+G22+I22 -> 0 | L22: =D22+F22+H22+J22 -> 69301.98 | M22: =K22-L22 -> -69301.98 | O22: ='6. SBQ'!A21+'6. SBQ'!B21+'6. SBQ'!C21 -> 0 | Q22: ='6. SBQ'!D21+'6. SBQ'!E21+'6. SBQ'!F21 -> 0 | S22: ='6. SBQ'!G21+'6. SBQ'!H21+'6. SBQ'!I21 -> 0 | U22: ='6. SBQ'!J21+'6. SBQ'!K21+'6. SBQ'!L21 -> 4750 | V22: =N22+P22+R22+T22 -> 0 | W22: =O22+Q22+S22+U22 -> 4750 | X22: =V22-W22 -> -4750 | Z22: ='6. SBQ'!A26+'6. SBQ'!B26+'6. SBQ'!C26 -> 6213.6 | AB22: ='6. SBQ'!D26+'6. SBQ'!E26+'6. SBQ'!F26 -> 70413.6 | AD22: ='6. SBQ'!G26+'6. SBQ'!H26+'6. SBQ'!I26 -> 0 | AF22: ='6. SBQ'!J26+'6. SBQ'!K26+'6. SBQ'!L26 -> 0 | AG22: =Y22+AA22+AC22+AE22 -> 0 | AH22: =Z22+AB22+AD22+AF22 -> 76627.2 | AI22: =AG22-AH22 -> -76627.2 | AJ22: 50182 | AK22: ='6. SBQ'!A31+'6. SBQ'!B31+'6. SBQ'!C31 -> 0 | AL22: 50182 | AM22: ='6. SBQ'!D31+'6. SBQ'!E31+'6. SBQ'!F31 -> 10116 | AN22: 50182 | AO22: ='6. SBQ'!G31+'6. SBQ'!H31+'6. SBQ'!I31 -> 0 | AP22: 50182 | AQ22: ='6. SBQ'!J31+'6. SBQ'!K31+'6. SBQ'!L31 -> 0 | AR22: =AJ22+AL22+AN22+AP22 -> 200728 | AS22: =AK22+AM22+AO22+AQ22 -> 10116 | AT22: =AR22-AS22 -> 190612 | AU22: 50182 | AV22: ='6. SBQ'!A36+'6. SBQ'!B36+'6. SBQ'!C36 -> 0 | AW22: 50182 | AX22: ='6. SBQ'!D36+'6. SBQ'!E36+'6. SBQ'!F36 -> 0 | AY22: 50182 | AZ22: ='6. SBQ'!G36+'6. SBQ'!H36+'6. SBQ'!I36 -> 0 | BA22: 50182 | BB22: ='6. SBQ'!J36+'6. SBQ'!K36+'6. SBQ'!L36 -> 0 | BC22: =AU22+AW22+AY22+BA22 -> 200728 | BD22: =AV22+AX22+AZ22+BB22 -> 0 | BE22: =BC22-BD22 -> 200728
A23: Aptamer | B23: KRW | K23: =C23+E23+G23+I23 -> 0 | L23: =D23+F23+H23+J23 -> 0 | M23: =K23-L23 -> 0 | V23: =N23+P23+R23+T23 -> 0 | W23: =O23+Q23+S23+U23 -> 0 | X23: =V23-W23 -> 0 | Z23: ='7. Aptamer'!A16+'7. Aptamer'!B16+'7. Aptamer'!C16 -> 0 | AB23: ='7. Aptamer'!D16+'7. Aptamer'!E16+'7. Aptamer'!F16 -> 14190000 | AD23: ='7. Aptamer'!G16+'7. Aptamer'!H16+'7. Aptamer'!I16 -> 0 | AE23: 36600000 | AF23: ='7. Aptamer'!J16+'7. Aptamer'!K16+'7. Aptamer'!L16 -> 40260000 | AG23: =Y23+AA23+AC23+AE23 -> 36600000 | AH23: =Z23+AB23+AD23+AF23 -> 54450000 | AI23: =AG23-AH23 -> -17850000 | AJ23: 33777000 | AK23: ='7. Aptamer'!A20+'7. Aptamer'!B20+'7. Aptamer'!C20 -> 0 | AL23: 59577000 | AM23: ='7. Aptamer'!D20+'7. Aptamer'!E20+'7. Aptamer'!F20 -> 0 | AN23: 43377000 | AO23: ='7. Aptamer'!G20+'7. Aptamer'!H20+'7. Aptamer'!I20 -> 0 | AP23: 28377000 | AQ23: ='7. Aptamer'!J20+'7. Aptamer'!K20+'7. Aptamer'!L20 -> 0 | AR23: =AJ23+AL23+AN23+AP23 -> 165108000 | AS23: =AK23+AM23+AO23+AQ23 -> 0 | AT23: =AR23-AS23 -> 165108000 | AU23: 35154000 | AV23: ='7. Aptamer'!A24+'7. Aptamer'!B24+'7. Aptamer'!C24 -> 0 | AW23: 38700000 | AX23: ='7. Aptamer'!D24+'7. Aptamer'!E24+'7. Aptamer'!F24 -> 0 | AZ23: ='7. Aptamer'!G24+'7. Aptamer'!H24+'7. Aptamer'!I24 -> 0 | BB23: ='7. Aptamer'!J24+'7. Aptamer'!K24+'7. Aptamer'!L24 -> 0 | BC23: =AU23+AW23+AY23+BA23 -> 73854000 | BD23: =AV23+AX23+AZ23+BB23 -> 0 | BE23: =BC23-BD23 -> 73854000
A24: Invivo | B24: USD | K24: =C24+E24+G24+I24 -> 0 | L24: =D24+F24+H24+J24 -> 0 | M24: =K24-L24 -> 0 | V24: =N24+P24+R24+T24 -> 0 | W24: =O24+Q24+S24+U24 -> 0 | X24: =V24-W24 -> 0 | Z24: ='8. Invivo'!A16+'8. Invivo'!B16+'8. Invivo'!C16 -> 0 | AB24: ='8. Invivo'!D16+'8. Invivo'!E16+'8. Invivo'!F16 -> 0 | AD24: ='8. Invivo'!G16+'8. Invivo'!H16+'8. Invivo'!I16 -> 166689 | AE24: 10499 | AF24: ='8. Invivo'!J16+'8. Invivo'!K16+'8. Invivo'!L16 -> 17748.87 | AG24: =Y24+AA24+AC24+AE24 -> 10499 | AH24: =Z24+AB24+AD24+AF24 -> 184437.87 | AI24: =AG24-AH24 -> -173938.87 | AJ24: 15748 | AK24: ='8. Invivo'!A21+'8. Invivo'!B21+'8. Invivo'!C21 -> 13484.15 | AL24: 15748 | AM24: ='8. Invivo'!D21+'8. Invivo'!E21+'8. Invivo'!F21 -> 15220.34 | AN24: 15748 | AO24: ='8. Invivo'!G21+'8. Invivo'!H21+'8. Invivo'!I21 -> 0 | AP24: 15748 | AQ24: ='8. Invivo'!J21+'8. Invivo'!K21+'8. Invivo'!L21 -> 0 | AR24: =AJ24+AL24+AN24+AP24 -> 62992 | AS24: =AK24+AM24+AO24+AQ24 -> 28704.49 | AT24: =AR24-AS24 -> 34287.51 | AU24: 20998 | AV24: ='8. Invivo'!A26+'8. Invivo'!B26+'8. Invivo'!C26 -> 0 | AX24: ='8. Invivo'!D26+'8. Invivo'!E26+'8. Invivo'!F26 -> 0 | AZ24: ='8. Invivo'!G26+'8. Invivo'!H26+'8. Invivo'!I26 -> 0 | BB24: ='8. Invivo'!J26+'8. Invivo'!K26+'8. Invivo'!L26 -> 0 | BC24: =AU24+AW24+AY24+BA24 -> 20998 | BD24: =AV24+AX24+AZ24+BB24 -> 0 | BE24: =BC24-BD24 -> 20998
A25: Labconnect | B25: USD | K25: =C25+E25+G25+I25 -> 0 | L25: =D25+F25+H25+J25 -> 0 | M25: =K25-L25 -> 0 | V25: =N25+P25+R25+T25 -> 0 | W25: =O25+Q25+S25+U25 -> 0 | X25: =V25-W25 -> 0 | Z25: ='9. Labconnect'!A16+'9. Labconnect'!B16+'9. Labconnect'!C16 -> 0 | AB25: ='9. Labconnect'!D16+'9. Labconnect'!E16+'9. Labconnect'!F16 -> 0 | AD25: ='9. Labconnect'!G16+'9. Labconnect'!H16+'9. Labconnect'!I16 -> 45130 | AE25: 5413 | AF25: ='9. Labconnect'!J16+'9. Labconnect'!K16+'9. Labconnect'!L16 -> 832.23 | AG25: =Y25+AA25+AC25+AE25 -> 5413 | AH25: =Z25+AB25+AD25+AF25 -> 45962.23 | AI25: =AG25-AH25 -> -40549.23 | AJ25: 8120 | AK25: ='9. Labconnect'!A21+'9. Labconnect'!B21+'9. Labconnect'!C21 -> 0 | AL25: 8120 | AM25: ='9. Labconnect'!D21+'9. Labconnect'!E21+'9. Labconnect'!F21 -> 0 | AN25: 8120 | AO25: ='9. Labconnect'!G21+'9. Labconnect'!H21+'9. Labconnect'!I21 -> 0 | AP25: 8120 | AQ25: ='9. Labconnect'!J21+'9. Labconnect'!K21+'9. Labconnect'!L21 -> 0 | AR25: =AJ25+AL25+AN25+AP25 -> 32480 | AS25: =AK25+AM25+AO25+AQ25 -> 0 | AT25: =AR25-AS25 -> 32480 | AU25: 10826 | AV25: ='9. Labconnect'!A26+'9. Labconnect'!B26+'9. Labconnect'!C26 -> 0 | AX25: ='9. Labconnect'!D26+'9. Labconnect'!E26+'9. Labconnect'!F26 -> 0 | AZ25: ='9. Labconnect'!G26+'9. Labconnect'!H26+'9. Labconnect'!I26 -> 0 | BB25: ='9. Labconnect'!J26+'9. Labconnect'!K26+'9. Labconnect'!L26 -> 0 | BC25: =AU25+AW25+AY25+BA25 -> 10826 | BD25: =AV25+AX25+AZ25+BB25 -> 0 | BE25: =BC25-BD25 -> 10826
A26: AIMS | B26: KRW | D26: ='10. AIMS'!A16+'10. AIMS'!B16+'10. AIMS'!C16 -> 0 | F26: ='10. AIMS'!D16+'10. AIMS'!E16+'10. AIMS'!F16 -> 0 | H26: ='10. AIMS'!G16+'10. AIMS'!H16+'10. AIMS'!I16 -> 0 | J26: ='10. AIMS'!J16+'10. AIMS'!K16+'10. AIMS'!L16 -> 23650000 | K26: =C26+E26+G26+I26 -> 0 | L26: =D26+F26+H26+J26 -> 23650000 | M26: =K26-L26 -> -23650000 | O26: ='10. AIMS'!A20+'10. AIMS'!B20+'10. AIMS'!C20 -> 0 | Q26: ='10. AIMS'!D20+'10. AIMS'!E20+'10. AIMS'!F20 -> 0 | S26: ='10. AIMS'!G20+'10. AIMS'!H20+'10. AIMS'!I20 -> 53399500 | U26: ='10. AIMS'!J20+'10. AIMS'!K20+'10. AIMS'!L20 -> 46695000 | V26: =N26+P26+R26+T26 -> 0 | W26: =O26+Q26+S26+U26 -> 100094500 | X26: =V26-W26 -> -100094500 | Z26: ='10. AIMS'!A24+'10. AIMS'!B24+'10. AIMS'!C24 -> 50160000 | AB26: ='10. AIMS'!D24+'10. AIMS'!E24+'10. AIMS'!F24 -> 23650000 | AD26: ='10. AIMS'!G24+'10. AIMS'!H24+'10. AIMS'!I24 -> 0 | AF26: ='10. AIMS'!J24+'10. AIMS'!K24+'10. AIMS'!L24 -> 44067100 | AG26: =Y26+AA26+AC26+AE26 -> 0 | AH26: =Z26+AB26+AD26+AF26 -> 117877100 | AI26: =AG26-AH26 -> -117877100 | AJ26: 33000000 | AK26: ='10. AIMS'!A28+'10. AIMS'!B28+'10. AIMS'!C28 -> 8976000 | AM26: ='10. AIMS'!D28+'10. AIMS'!E28+'10. AIMS'!F28 -> 0 | AN26: 9075000 | AO26: ='10. AIMS'!G28+'10. AIMS'!H28+'10. AIMS'!I28 -> 0 | AQ26: ='10. AIMS'!J28+'10. AIMS'!K28+'10. AIMS'!L28 -> 0 | AR26: =AJ26+AL26+AN26+AP26 -> 42075000 | AS26: =AK26+AM26+AO26+AQ26 -> 8976000 | AT26: =AR26-AS26 -> 33099000 | AU26: 12500000 | AV26: ='10. AIMS'!A32+'10. AIMS'!B32+'10. AIMS'!C32 -> 0 | AW26: 12500000 | AX26: ='10. AIMS'!D32+'10. AIMS'!E32+'10. AIMS'!F32 -> 0 | AY26: 12500000 | AZ26: ='10. AIMS'!G32+'10. AIMS'!H32+'10. AIMS'!I32 -> 0 | BA26: 12500000 | BB26: ='10. AIMS'!J32+'10. AIMS'!K32+'10. AIMS'!L32 -> 0 | BC26: =AU26+AW26+AY26+BA26 -> 50000000 | BD26: =AV26+AX26+AZ26+BB26 -> 0 | BE26: =BC26-BD26 -> 50000000
A30: Total (KRW) | B30: KRW | C30: =SUMIF($B$17:$B$29,$B30,C$17:C$29) -> 0 | D30: =SUMIF($B$17:$B$29,$B30,D$17:D$29) -> 0 | E30: =SUMIF($B$17:$B$29,$B30,E$17:E$29) -> 0 | F30: =SUMIF($B$17:$B$29,$B30,F$17:F$29) -> 6832940 | G30: =SUMIF($B$17:$B$29,$B30,G$17:G$29) -> 0 | H30: =SUMIF($B$17:$B$29,$B30,H$17:H$29) -> 42000 | I30: =SUMIF($B$17:$B$29,$B30,I$17:I$29) -> 0 | J30: =SUMIF($B$17:$B$29,$B30,J$17:J$29) -> 23650000 | ... BE30: =SUMIF($B$17:$B$29,$B30,BE$17:BE$29) -> 123854000
A31: Total (USD) | B31: USD | C31: =SUMIF($B$17:$B$29,$B31,C$17:C$29) -> 0 | D31: =SUMIF($B$17:$B$29,$B31,D$17:D$29) -> 12267 | E31: =SUMIF($B$17:$B$29,$B31,E$17:E$29) -> 0 | F31: =SUMIF($B$17:$B$29,$B31,F$17:F$29) -> 16333.47 | G31: =SUMIF($B$17:$B$29,$B31,G$17:G$29) -> 0 | H31: =SUMIF($B$17:$B$29,$B31,H$17:H$29) -> 46052.33 | I31: =SUMIF($B$17:$B$29,$B31,I$17:I$29) -> 0 | J31: =SUMIF($B$17:$B$29,$B31,J$17:J$29) -> 20282.86 | ... BE31: =SUMIF($B$17:$B$29,$B31,BE$17:BE$29) -> 1168927
A32: Total (CHF) | B32: CHF | C32: =SUMIF($B$17:$B$29,$B32,C$17:C$29) -> 0 | D32: =SUMIF($B$17:$B$29,$B32,D$17:D$29) -> 67333.98 | E32: =SUMIF($B$17:$B$29,$B32,E$17:E$29) -> 0 | F32: =SUMIF($B$17:$B$29,$B32,F$17:F$29) -> 0 | G32: =SUMIF($B$17:$B$29,$B32,G$17:G$29) -> 0 | H32: =SUMIF($B$17:$B$29,$B32,H$17:H$29) -> 1968 | I32: =SUMIF($B$17:$B$29,$B32,I$17:I$29) -> 0 | J32: =SUMIF($B$17:$B$29,$B32,J$17:J$29) -> 0 | ... BE32: =SUMIF($B$17:$B$29,$B32,BE$17:BE$29) -> 200728

Sheet 1. IQVIA 
A1: 1. CRO: IQVIA | F1: 1-1, 1-2 입력 시 자동 기입되는 페이지
B2: Contract Number: | C2: LAB97701 | D2: Version & date: | E2: CO1_23Sep2025
A4: Protocol No: TTK-CS-101 | D4: Updated on:
A6: 1. Total Payment Status
A7: Category | B7: $ | C7: %
A8: Budget | B8: 15935420
A9: Paid | B9: ='1-1. Direct'!B9+'1-2. PTC'!B10 -> 7387992.2 | C9: =B9/B8 -> 0.46362079
A10: Remaining | B10: =B8-B9 -> 8547428.3 | C10: =B10/B8 -> 0.53637921
A12: 2. Total Yearly and Monthly Payment
B13: USD | C13: KRW
A14: 2024 | B14: =SUM(A16:L16) -> 3069920.9 | C14: =SUM(A17:L17) -> 652255797
A15: 01 | B15: 02 | C15: 03 | D15: 04 | E15: 05 | F15: 06 | G15: 07 | H15: 08 | I15: 09 | J15: 10 | K15: 11 | L15: 12
A16: ='1-1. Direct'!A16+'1-2. PTC'!A17 -> 0 | B16: ='1-1. Direct'!B16+'1-2. PTC'!B17 -> 0 | C16: ='1-1. Direct'!C16+'1-2. PTC'!C17 -> 0 | D16: ='1-1. Direct'!D16+'1-2. PTC'!D17 -> 0 | E16: ='1-1. Direct'!E16+'1-2. PTC'!E17 -> 0 | F16: ='1-1. Direct'!F16+'1-2. PTC'!F17 -> 0 | G16: ='1-1. Direct'!G16+'1-2. PTC'!G17 -> 0 | H16: ='1-1. Direct'!H16+'1-2. PTC'!H17 -> 297156.95 | ... L16: ='1-1. Direct'!L16+'1-2. PTC'!L17 -> 664443.22
A17: ='1-1. Direct'!A17+'1-2. PTC'!A18 -> 0 | B17: ='1-1. Direct'!B17+'1-2. PTC'!B18 -> 0 | C17: ='1-1. Direct'!C17+'1-2. PTC'!C18 -> 0 | D17: ='1-1. Direct'!D17+'1-2. PTC'!D18 -> 0 | E17: ='1-1. Direct'!E17+'1-2. PTC'!E18 -> 0 | F17: ='1-1. Direct'!F17+'1-2. PTC'!F18 -> 0 | G17: ='1-1. Direct'!G17+'1-2. PTC'!G18 -> 0 | H17: ='1-1. Direct'!H17+'1-2. PTC'!H18 -> 445735425 | ... L17: ='1-1. Direct'!L17+'1-2. PTC'!L18 -> 45657
A19: 2025 | B19: =SUM(A21:L21) -> 3902245.9 | C19: =SUM(A22:L22) -> 275739
A20: 01 | B20: 02 | C20: 03 | D20: 04 | E20: 05 | F20: 06 | G20: 07 | H20: 08 | I20: 09 | J20: 10 | K20: 11 | L20: 12
A21: ='1-1. Direct'!A21+'1-2. PTC'!A22 -> 2603.63 | B21: ='1-1. Direct'!B21+'1-2. PTC'!B22 -> 3495.17 | C21: ='1-1. Direct'!C21+'1-2. PTC'!C22 -> 28596.55 | D21: ='1-1. Direct'!D21+'1-2. PTC'!D22 -> 602035.01 | E21: ='1-1. Direct'!E21+'1-2. PTC'!E22 -> 22753.1 | F21: ='1-1. Direct'!F21+'1-2. PTC'!F22 -> 31921.13 | G21: ='1-1. Direct'!G21+'1-2. PTC'!G22 -> 280003.73 | H21: ='1-1. Direct'!H21+'1-2. PTC'!H22 -> 549854.43 | ... L21: ='1-1. Direct'!L21+'1-2. PTC'!L22 -> 2110369
A22: ='1-1. Direct'!A22+'1-2. PTC'!A23 -> 0 | B22: ='1-1. Direct'!B22+'1-2. PTC'!B23 -> 0 | C22: ='1-1. Direct'!C22+'1-2. PTC'!C23 -> 0 | D22: ='1-1. Direct'!D22+'1-2. PTC'!D23 -> 45768 | E22: ='1-1. Direct'!E22+'1-2. PTC'!E23 -> 0 | F22: ='1-1. Direct'!F22+'1-2. PTC'!F23 -> 0 | G22: ='1-1. Direct'!G22+'1-2. PTC'!G23 -> 0 | H22: ='1-1. Direct'!H22+'1-2. PTC'!H23 -> 45891 | ... L22: ='1-1. Direct'!L22+'1-2. PTC'!L23 -> 138081
A24: 2026 | B24: =SUM(A26:L26) -> 2870923.4 | C24: =SUM(A27:L27) -> 184578
A25: 01 | B25: 02 | C25: 03 | D25: 04 | E25: 05 | F25: 06 | G25: 07 | H25: 08 | I25: 09 | J25: 10 | K25: 11 | L25: 12
A26: ='1-1. Direct'!A26+'1-2. PTC'!A27 -> 429677.89 | B26: ='1-1. Direct'!B26+'1-2. PTC'!B27 -> 471496.93 | C26: ='1-1. Direct'!C26+'1-2. PTC'!C27 -> 404131.92 | D26: ='1-1. Direct'!D26+'1-2. PTC'!D27 -> 253068.95 | E26: ='1-1. Direct'!E26+'1-2. PTC'!E27 -> 112404.17 | F26: ='1-1. Direct'!F26+'1-2. PTC'!F27 -> 1066065.7 | G26: ='1-1. Direct'!G26+'1-2. PTC'!G27 -> 134077.92 | H26: ='1-1. Direct'!H26+'1-2. PTC'!H27 -> 0 | ... L26: ='1-1. Direct'!L26+'1-2. PTC'!L27 -> 0
A27: ='1-1. Direct'!A27+'1-2. PTC'!A28 -> 0 | B27: ='1-1. Direct'!B27+'1-2. PTC'!B28 -> 46081 | C27: ='1-1. Direct'!C27+'1-2. PTC'!C28 -> 46096 | D27: ='1-1. Direct'!D27+'1-2. PTC'!D28 -> 0 | E27: ='1-1. Direct'!E27+'1-2. PTC'!E28 -> 0 | F27: ='1-1. Direct'!F27+'1-2. PTC'!F28 -> 92401 | G27: ='1-1. Direct'!G27+'1-2. PTC'!G28 -> 0 | H27: ='1-1. Direct'!H27+'1-2. PTC'!H28 -> 0 | ... L27: ='1-1. Direct'!L27+'1-2. PTC'!L28 -> 0
A29: 2027 | B29: =SUM(A31:L31) -> 0 | C29: =SUM(A32:L32) -> 0
A30: 01 | B30: 02 | C30: 03 | D30: 04 | E30: 05 | F30: 06 | G30: 07 | H30: 08 | I30: 09 | J30: 10 | K30: 11 | L30: 12
A31: ='1-1. Direct'!A31+'1-2. PTC'!A32 -> 0 | B31: ='1-1. Direct'!B31+'1-2. PTC'!B32 -> 0 | C31: ='1-1. Direct'!C31+'1-2. PTC'!C32 -> 0 | D31: ='1-1. Direct'!D31+'1-2. PTC'!D32 -> 0 | E31: ='1-1. Direct'!E31+'1-2. PTC'!E32 -> 0 | F31: ='1-1. Direct'!F31+'1-2. PTC'!F32 -> 0 | G31: ='1-1. Direct'!G31+'1-2. PTC'!G32 -> 0 | H31: ='1-1. Direct'!H31+'1-2. PTC'!H32 -> 0 | ... L31: ='1-1. Direct'!L31+'1-2. PTC'!L32 -> 0
A32: ='1-1. Direct'!A32+'1-2. PTC'!A33 -> 0 | B32: ='1-1. Direct'!B32+'1-2. PTC'!B33 -> 0 | C32: ='1-1. Direct'!C32+'1-2. PTC'!C33 -> 0 | D32: ='1-1. Direct'!D32+'1-2. PTC'!D33 -> 0 | E32: ='1-1. Direct'!E32+'1-2. PTC'!E33 -> 0 | F32: ='1-1. Direct'!F32+'1-2. PTC'!F33 -> 0 | G32: ='1-1. Direct'!G32+'1-2. PTC'!G33 -> 0 | H32: ='1-1. Direct'!H32+'1-2. PTC'!H33 -> 0 | ... L32: ='1-1. Direct'!L32+'1-2. PTC'!L33 -> 0
A34: 3. Contract Details
A35: Team FTE | B35: Initial | C35: Country | D35: CO1 | E35: Country
A36: Project Lead (PL) | D36: 0.54 | E36: KR
A37: PL Oversight | D37: 0.08 | E37: KR
A38: Transition Lead | D38: 0.01 | E38: KR
A39: Project Management Associate (PMA) | D39: 0.34 | E39: IN
A40: Clinical Lead (CL) KR | D40: 0.54 | E40: KR
A41: Clinical Lead (CL) US | D41: 0.39 | E41: BR
A42: Clinical Monitoring Lead (CML) | D42: 0.27 | E42: IN
B44: Initial | E44: CO1 | H44: Change
A45: Milestones | B45: Duration(Months) | C45: Start Date | D45: End Date | E45: Duration(Months) | F45: Start Date | G45: End Date | H45: Initial to CO1
A46: Pre-Study Activities : ATP/Contract Signed to Final Protocol | E46: 0.46 | F46: 45473 | G46: 45487 | H46: =B46-E46 -> -0.46
A47: Start-Up: Final Protocol to FPI | E47: 2.56 | F47: 45488 | G47: 45565 | H47: =B47-E47 -> -2.56
A48: Recruitment: FPI to LPI | E48: 24.72 | F48: 45566 | G48: 46316 | H48: =B48-E48 -> -24.72
...

Sheet 1-1. Direct
A1: 1. CRO: IQVIA
B2: Contract Number: | C2: LAB97701 | D2: Version & date: | E2: CO1_23Sep2025
A4: Protocol No: TTK-CS-101 | D4: Updated on:
A6: 1. Sub Total Direct Cost Status
A7: Category | B7: $ | C7: %
A8: Budget | B8: ='1. IQVIA '!F85 -> 6735531.8
A9: Paid | B9: =B14+B19+B24+B29 -> 5896792.5 | C9: =B9/B8 -> 0.87547542
A10: Remaining | B10: =B8-B9 -> 838739.25 | C10: =B10/B8 -> 0.12452458
A12: 2. Direct Cost Yearly and Monthly Payment
B13: USD | C13: KRW
A14: 2024 | B14: =SUM(A16:L16) -> 1654541.9 | C14: =SUM(A17:L17) -> 406105797
A15: 01 | B15: 02 | C15: 03 | D15: 04 | E15: 05 | F15: 06 | G15: 07 | H15: 08 | I15: 09 | J15: 10 | K15: 11 | L15: 12
A16: =SUMIFS($C$36:$C$57,$F$36:$F$57,2024,$G$36:$G$57,1,$J$36:$J$57,"Y") -> 0 | B16: =SUMIFS($C$36:$C$57,$F$36:$F$57,2024,$G$36:$G$57,2,$J$36:$J$57,"Y") -> 0 | C16: =SUMIFS($C$36:$C$57,$F$36:$F$57,2024,$G$36:$G$57,3,$J$36:$J$57,"Y") -> 0 | D16: =SUMIFS($C$36:$C$57,$F$36:$F$57,2024,$G$36:$G$57,4,$J$36:$J$57,"Y") -> 0 | E16: =SUMIFS($C$36:$C$57,$F$36:$F$57,2024,$G$36:$G$57,5,$J$36:$J$57,"Y") -> 0 | F16: =SUMIFS($C$36:$C$57,$F$36:$F$57,2024,$G$36:$G$57,6,$J$36:$J$57,"Y") -> 0 | G16: =SUMIFS($C$36:$C$57,$F$36:$F$57,2024,$G$36:$G$57,7,$J$36:$J$57,"Y") -> 0 | H16: =SUMIFS($C$36:$C$57,$F$36:$F$57,2024,$G$36:$G$57,8,$J$36:$J$57,"Y") -> 270676.37 | I16: =SUMIFS($C$36:$C$57,$F$36:$F$57,2024,$G$36:$G$57,9,$J$36:$J$57,"Y") -> 0 | J16: =SUMIFS($C$36:$C$57,$F$36:$F$57,2024,$G$36:$G$57,10,$J$36:$J$57,"Y") -> 722048.76 | K16: =SUMIFS($C$36:$C$57,$F$36:$F$57,2024,$G$36:$G$57,11,$J$36:$J$57,"Y") -> 0 | L16: =SUMIFS($C$36:$C$57,$F$36:$F$57,2024,$G$36:$G$57,12,$J$36:$J$57,"Y") -> 661816.76
A17: =SUMIFS($I$36:$I$57,$F$36:$F$57,2024,$G$36:$G$57,1,$J$36:$J$57,"Y") -> 0 | B17: =SUMIFS($I$36:$I$57,$F$36:$F$57,2024,$G$36:$G$57,2,$J$36:$J$57,"Y") -> 0 | C17: =SUMIFS($I$36:$I$57,$F$36:$F$57,2024,$G$36:$G$57,3,$J$36:$J$57,"Y") -> 0 | D17: =SUMIFS($I$36:$I$57,$F$36:$F$57,2024,$G$36:$G$57,4,$J$36:$J$57,"Y") -> 0 | E17: =SUMIFS($I$36:$I$57,$F$36:$F$57,2024,$G$36:$G$57,5,$J$36:$J$57,"Y") -> 0 | F17: =SUMIFS($I$36:$I$57,$F$36:$F$57,2024,$G$36:$G$57,6,$J$36:$J$57,"Y") -> 0 | G17: =SUMIFS($I$36:$I$57,$F$36:$F$57,2024,$G$36:$G$57,7,$J$36:$J$57,"Y") -> 0 | H17: =SUMIFS($I$36:$I$57,$F$36:$F$57,2024,$G$36:$G$57,8,$J$36:$J$57,"Y") -> 406014555 | I17: =SUMIFS($I$36:$I$57,$F$36:$F$57,2024,$G$36:$G$57,9,$J$36:$J$57,"Y") -> 0 | J17: =SUMIFS($I$36:$I$57,$F$36:$F$57,2024,$G$36:$G$57,10,$J$36:$J$57,"Y") -> 45585 | K17: =SUMIFS($I$36:$I$57,$F$36:$F$57,2024,$G$36:$G$57,11,$J$36:$J$57,"Y") -> 0 | L17: =SUMIFS($I$36:$I$57,$F$36:$F$57,2024,$G$36:$G$57,12,$J$36:$J$57,"Y") -> 45657
A19: 2025 | B19: =SUM(A21:L21) -> 2625713.3 | C19: =SUM(A22:L22) -> 275739
A20: 01 | B20: 02 | C20: 03 | D20: 04 | E20: 05 | F20: 06 | G20: 07 | H20: 08 | I20: 09 | J20: 10 | K20: 11 | L20: 12
A21: =SUMIFS($C$36:$C$57,$F$36:$F$57,2025,$G$36:$G$57,1,$J$36:$J$57,"Y") -> 0 | B21: =SUMIFS($C$36:$C$57,$F$36:$F$57,2025,$G$36:$G$57,2,$J$36:$J$57,"Y") -> 0 | C21: =SUMIFS($C$36:$C$57,$F$36:$F$57,2025,$G$36:$G$57,3,$J$36:$J$57,"Y") -> 0 | D21: =SUMIFS($C$36:$C$57,$F$36:$F$57,2025,$G$36:$G$57,4,$J$36:$J$57,"Y") -> 595635.08 | E21: =SUMIFS($C$36:$C$57,$F$36:$F$57,2025,$G$36:$G$57,5,$J$36:$J$57,"Y") -> 0 | F21: =SUMIFS($C$36:$C$57,$F$36:$F$57,2025,$G$36:$G$57,6,$J$36:$J$57,"Y") -> 0 | G21: =SUMIFS($C$36:$C$57,$F$36:$F$57,2025,$G$36:$G$57,7,$J$36:$J$57,"Y") -> 0 | H21: =SUMIFS($C$36:$C$57,$F$36:$F$57,2025,$G$36:$G$57,8,$J$36:$J$57,"Y") -> 463271.73 | I21: =SUMIFS($C$36:$C$57,$F$36:$F$57,2025,$G$36:$G$57,9,$J$36:$J$57,"Y") -> 0 | J21: =SUMIFS($C$36:$C$57,$F$36:$F$57,2025,$G$36:$G$57,10,$J$36:$J$57,"Y") -> 0 | K21: =SUMIFS($C$36:$C$57,$F$36:$F$57,2025,$G$36:$G$57,11,$J$36:$J$57,"Y") -> 17605 | L21: =SUMIFS($C$36:$C$57,$F$36:$F$57,2025,$G$36:$G$57,12,$J$36:$J$57,"Y") -> 1549201.5
A22: =SUMIFS($I$36:$I$57,$F$36:$F$57,2025,$G$36:$G$57,1,$J$36:$J$57,"Y") -> 0 | B22: =SUMIFS($I$36:$I$57,$F$36:$F$57,2025,$G$36:$G$57,2,$J$36:$J$57,"Y") -> 0 | C22: =SUMIFS($I$36:$I$57,$F$36:$F$57,2025,$G$36:$G$57,3,$J$36:$J$57,"Y") -> 0 | D22: =SUMIFS($I$36:$I$57,$F$36:$F$57,2025,$G$36:$G$57,4,$J$36:$J$57,"Y") -> 45768 | E22: =SUMIFS($I$36:$I$57,$F$36:$F$57,2025,$G$36:$G$57,5,$J$36:$J$57,"Y") -> 0 | F22: =SUMIFS($I$36:$I$57,$F$36:$F$57,2025,$G$36:$G$57,6,$J$36:$J$57,"Y") -> 0 | G22: =SUMIFS($I$36:$I$57,$F$36:$F$57,2025,$G$36:$G$57,7,$J$36:$J$57,"Y") -> 0 | H22: =SUMIFS($I$36:$I$57,$F$36:$F$57,2025,$G$36:$G$57,8,$J$36:$J$57,"Y") -> 45891 | I22: =SUMIFS($I$36:$I$57,$F$36:$F$57,2025,$G$36:$G$57,9,$J$36:$J$57,"Y") -> 0 | J22: =SUMIFS($I$36:$I$57,$F$36:$F$57,2025,$G$36:$G$57,10,$J$36:$J$57,"Y") -> 0 | K22: =SUMIFS($I$36:$I$57,$F$36:$F$57,2025,$G$36:$G$57,11,$J$36:$J$57,"Y") -> 45999 | L22: =SUMIFS($I$36:$I$57,$F$36:$F$57,2025,$G$36:$G$57,12,$J$36:$J$57,"Y") -> 138081
A24: 2026 | B24: =SUM(A26:L26) -> 1616537.4 | C24: =SUM(A27:L27) -> 184578
A25: 01 | B25: 02 | C25: 03 | D25: 04 | E25: 05 | F25: 06 | G25: 07 | H25: 08 | I25: 09 | J25: 10 | K25: 11 | L25: 12
A26: =SUMIFS($C$36:$C$57,$F$36:$F$57,2026,$G$36:$G$57,1,$J$36:$J$57,"Y") -> 0 | B26: =SUMIFS($C$36:$C$57,$F$36:$F$57,2026,$G$36:$G$57,2,$J$36:$J$57,"Y") -> 471496.93 | C26: =SUMIFS($C$36:$C$57,$F$36:$F$57,2026,$G$36:$G$57,3,$J$36:$J$57,"Y") -> 404131.92 | D26: =SUMIFS($C$36:$C$57,$F$36:$F$57,2026,$G$36:$G$57,4,$J$36:$J$57,"Y") -> 0 | E26: =SUMIFS($C$36:$C$57,$F$36:$F$57,2026,$G$36:$G$57,5,$J$36:$J$57,"Y") -> 0 | F26: =SUMIFS($C$36:$C$57,$F$36:$F$57,2026,$G$36:$G$57,6,$J$36:$J$57,"Y") -> 740908.51 | G26: =SUMIFS($C$36:$C$57,$F$36:$F$57,2026,$G$36:$G$57,7,$J$36:$J$57,"Y") -> 0 | H26: =SUMIFS($C$36:$C$57,$F$36:$F$57,2026,$G$36:$G$57,8,$J$36:$J$57,"Y") -> 0 | I26: =SUMIFS($C$36:$C$57,$F$36:$F$57,2026,$G$36:$G$57,9,$J$36:$J$57,"Y") -> 0 | J26: =SUMIFS($C$36:$C$57,$F$36:$F$57,2026,$G$36:$G$57,10,$J$36:$J$57,"Y") -> 0 | K26: =SUMIFS($C$36:$C$57,$F$36:$F$57,2026,$G$36:$G$57,11,$J$36:$J$57,"Y") -> 0 | L26: =SUMIFS($C$36:$C$57,$F$36:$F$57,2026,$G$36:$G$57,12,$J$36:$J$57,"Y") -> 0
A27: =SUMIFS($I$36:$I$57,$F$36:$F$57,2026,$G$36:$G$57,1,$J$36:$J$57,"Y") -> 0 | B27: =SUMIFS($I$36:$I$57,$F$36:$F$57,2026,$G$36:$G$57,2,$J$36:$J$57,"Y") -> 46081 | C27: =SUMIFS($I$36:$I$57,$F$36:$F$57,2026,$G$36:$G$57,3,$J$36:$J$57,"Y") -> 46096 | D27: =SUMIFS($I$36:$I$57,$F$36:$F$57,2026,$G$36:$G$57,4,$J$36:$J$57,"Y") -> 0 | E27: =SUMIFS($I$36:$I$57,$F$36:$F$57,2026,$G$36:$G$57,5,$J$36:$J$57,"Y") -> 0 | F27: =SUMIFS($I$36:$I$57,$F$36:$F$57,2026,$G$36:$G$57,6,$J$36:$J$57,"Y") -> 92401 | G27: =SUMIFS($I$36:$I$57,$F$36:$F$57,2026,$G$36:$G$57,7,$J$36:$J$57,"Y") -> 0 | H27: =SUMIFS($I$36:$I$57,$F$36:$F$57,2026,$G$36:$G$57,8,$J$36:$J$57,"Y") -> 0 | I27: =SUMIFS($I$36:$I$57,$F$36:$F$57,2026,$G$36:$G$57,9,$J$36:$J$57,"Y") -> 0 | J27: =SUMIFS($I$36:$I$57,$F$36:$F$57,2026,$G$36:$G$57,10,$J$36:$J$57,"Y") -> 0 | K27: =SUMIFS($I$36:$I$57,$F$36:$F$57,2026,$G$36:$G$57,11,$J$36:$J$57,"Y") -> 0 | L27: =SUMIFS($I$36:$I$57,$F$36:$F$57,2026,$G$36:$G$57,12,$J$36:$J$57,"Y") -> 0
A29: 2027 | B29: =SUM(A31:L31) -> 0 | C29: =SUM(A32:L32) -> 0
A30: 01 | B30: 02 | C30: 03 | D30: 04 | E30: 05 | F30: 06 | G30: 07 | H30: 08 | I30: 09 | J30: 10 | K30: 11 | L30: 12
A31: =SUMIFS($C$36:$C$57,$F$36:$F$57,2027,$G$36:$G$57,1,$J$36:$J$57,"Y") -> 0 | B31: =SUMIFS($C$36:$C$57,$F$36:$F$57,2027,$G$36:$G$57,2,$J$36:$J$57,"Y") -> 0 | C31: =SUMIFS($C$36:$C$57,$F$36:$F$57,2027,$G$36:$G$57,3,$J$36:$J$57,"Y") -> 0 | D31: =SUMIFS($C$36:$C$57,$F$36:$F$57,2027,$G$36:$G$57,4,$J$36:$J$57,"Y") -> 0 | E31: =SUMIFS($C$36:$C$57,$F$36:$F$57,2027,$G$36:$G$57,5,$J$36:$J$57,"Y") -> 0 | F31: =SUMIFS($C$36:$C$57,$F$36:$F$57,2027,$G$36:$G$57,6,$J$36:$J$57,"Y") -> 0 | G31: =SUMIFS($C$36:$C$57,$F$36:$F$57,2027,$G$36:$G$57,7,$J$36:$J$57,"Y") -> 0 | H31: =SUMIFS($C$36:$C$57,$F$36:$F$57,2027,$G$36:$G$57,8,$J$36:$J$57,"Y") -> 0 | I31: =SUMIFS($C$36:$C$57,$F$36:$F$57,2027,$G$36:$G$57,9,$J$36:$J$57,"Y") -> 0 | J31: =SUMIFS($C$36:$C$57,$F$36:$F$57,2027,$G$36:$G$57,10,$J$36:$J$57,"Y") -> 0 | K31: =SUMIFS($C$36:$C$57,$F$36:$F$57,2027,$G$36:$G$57,11,$J$36:$J$57,"Y") -> 0 | L31: =SUMIFS($C$36:$C$57,$F$36:$F$57,2027,$G$36:$G$57,12,$J$36:$J$57,"Y") -> 0
A32: =SUMIFS($I$36:$I$57,$F$36:$F$57,2027,$G$36:$G$57,1,$J$36:$J$57,"Y") -> 0 | B32: =SUMIFS($I$36:$I$57,$F$36:$F$57,2027,$G$36:$G$57,2,$J$36:$J$57,"Y") -> 0 | C32: =SUMIFS($I$36:$I$57,$F$36:$F$57,2027,$G$36:$G$57,3,$J$36:$J$57,"Y") -> 0 | D32: =SUMIFS($I$36:$I$57,$F$36:$F$57,2027,$G$36:$G$57,4,$J$36:$J$57,"Y") -> 0 | E32: =SUMIFS($I$36:$I$57,$F$36:$F$57,2027,$G$36:$G$57,5,$J$36:$J$57,"Y") -> 0 | F32: =SUMIFS($I$36:$I$57,$F$36:$F$57,2027,$G$36:$G$57,6,$J$36:$J$57,"Y") -> 0 | G32: =SUMIFS($I$36:$I$57,$F$36:$F$57,2027,$G$36:$G$57,7,$J$36:$J$57,"Y") -> 0 | H32: =SUMIFS($I$36:$I$57,$F$36:$F$57,2027,$G$36:$G$57,8,$J$36:$J$57,"Y") -> 0 | I32: =SUMIFS($I$36:$I$57,$F$36:$F$57,2027,$G$36:$G$57,9,$J$36:$J$57,"Y") -> 0 | J32: =SUMIFS($I$36:$I$57,$F$36:$F$57,2027,$G$36:$G$57,10,$J$36:$J$57,"Y") -> 0 | K32: =SUMIFS($I$36:$I$57,$F$36:$F$57,2027,$G$36:$G$57,11,$J$36:$J$57,"Y") -> 0 | L32: =SUMIFS($I$36:$I$57,$F$36:$F$57,2027,$G$36:$G$57,12,$J$36:$J$57,"Y") -> 0
A34: 3. Direct Costs Details
A35: Milestones | B35: Budget Amount($) | C35: Invoiced Amount($) | D35: Invoice # | E35: Invoiced Date | F35: Paid Year | G35: Paid Month | H35: Paid Date | I35: Total Amount(₩) | J35: Paid (Y) | K35: 지출결의 #
A36: Pre-Payment Due Upon ATP Execution | B36: 270676.37 | C36: 270676.37 | D36: SGP-030213 | E36: 45495 | F36: 2024 | G36: 8 | H36: 45512 | I36: 406014555 | J36: Y | K36: CD24-170
A37: Pre-Payment Due Upon WO Execution | B37: 722048.76 | C37: 722048.76 | D37: SGP-030533 | E37: 45562 | F37: 2024 | G37: 10 | H37: 45575 | I37: =G37+H37 -> 45585 | J37: Y | K37: CD24-220
A38: Sign off transition checklist | B38: 661816.76 | C38: 661816.76 | D38: SGP-030822 | E38: 45625 | F38: 2024 | G38: 12 | H38: 45645 | I38: =G38+H38 -> 45657 | J38: Y | K38: CD24-277
A39: First IRB submission of AML site | B39: 595635.08 | C39: 595635.08 | D39: SGP-031343 | E39: 45755 | F39: 2025 | G39: 4 | H39: 45764 | I39: =G39+H39 -> 45768 | J39: Y | K39: CD25-072
A40: First IRB approval of AML site | B40: 463271.73 | C40: 463271.73 | D40: SGP-031701 | E40: 45852 | F40: 2025 | G40: 8 | H40: 45883 | I40: =G40+H40 -> 45891 | J40: Y | K40: CD25-155
A41: Pre-payment upon CO1 Execution | B41: 17605 | C41: 17605 | D41: SGP-032017 | E41: 45938 | F41: 2025 | G41: 11 | H41: 45988 | I41: =G41+H41 -> 45999 | J41: Y | K41: CD25-205
A42: First SIV for additional solid tumor site | B42: 606207.57 | C42: 606207.57 | D42: SGP-032306 | E42: 46001 | F42: 2025 | G42: 12 | H42: 46015 | I42: =G42+H42 -> 46027 | J42: Y | K42: CD25-232
A43: 30% of Monitoring Visits & Reports Completed | B43: 471496.93 | C43: 471496.96 | D43: SGP-032306 | E43: 46001 | F43: 2025 | G43: 12 | H43: 46015 | I43: =G43+H43 -> 46027 | J43: Y | K43: CD25-232
A44: 80% of Site Initiation Visits & Reports Completed | B44: 471496.93 | C44: 471496.93 | D44: SGP-032465 | E44: 46042 | F44: 2026 | G44: 2 | H44: 46079 | I44: =G44+H44 -> 46081 | J44: Y | K44: CD26-016
A45: 25% of Monitoring Visits & Reports Completed | B45: 471496.93 | C45: 471496.93 | D45: SGP-032175 | E45: 45970 | F45: 2025 | G45: 12 | H45: 46015 | I45: =G45+H45 -> 46027 | J45: Y | K45: CD25-225
A46: 35% of Monitoring Visits & Reports Completed | B46: 404131.92 | C46: 404131.92 | D46: SGP-032533 | E46: 46063 | F46: 2026 | G46: 3 | H46: 46093 | I46: =G46+H46 -> 46096 | J46: Y | K46: CD26-023
A47: 40% of Monitoring Visits & Reports Completed | B47: 404131.92 | C47: 404131.92 | D47: SGP-032889 | E47: 46155 | F47: 2026 | G47: 6 | H47: 46177 | I47: =G47+H47 -> 46183 | J47: Y | K47: CO26-025
...

Sheet 1-2. PTC
A1: 1. CRO: IQVIA
B2: Contract Number: | C2: LAB97701 | D2: Version & date: | E2: CO1_23Sep2025
A4: Protocol No: TTK-CS-101 | D4: Updated on:
A6: 1. Sub Total PTC Status
A7: Category | B7: $ | C7: %
A8: Budget | B8: 9199888.7
A9: Advance(Deposit) | D9: 연구 종료 시 Reconcilation 예정이므로 paid에서 제외
A10: Paid | B10: =B36+B41+B46+B51 -> 1491199.7 | C10: =B10/B8 -> 0.16208888
A11: Remaining | B11: =B8-B10 -> 7708689 | C11: =B11/B8 -> 0.83791112
A13: 2. PTC Yearly and Monthly Payment
B14: USD | C14: KRW
A15: 2024 | B15: =SUM(A17:L17) -> 1415379 | C15: =SUM(A18:L18) -> 2.4615e+08
A16: 01 | B16: 02 | C16: 03 | D16: 04 | E16: 05 | F16: 06 | G16: 07 | H16: 08 | I16: 09 | J16: 10 | K16: 11 | L16: 12
A17: =SUMIFS($P$41:$P$60,$R$41:$R$60,2024,$S$41:$S$60,1,$V$41:$V$60,"Y") -> 0 | B17: =SUMIFS($P$41:$P$60,$R$41:$R$60,2024,$S$41:$S$60,2,$V$41:$V$60,"Y") -> 0 | C17: =SUMIFS($P$41:$P$60,$R$41:$R$60,2024,$S$41:$S$60,3,$V$41:$V$60,"Y") -> 0 | D17: =SUMIFS($P$41:$P$60,$R$41:$R$60,2024,$S$41:$S$60,4,$V$41:$V$60,"Y") -> 0 | E17: =SUMIFS($P$41:$P$60,$R$41:$R$60,2024,$S$41:$S$60,5,$V$41:$V$60,"Y") -> 0 | F17: =SUMIFS($P$41:$P$60,$R$41:$R$60,2024,$S$41:$S$60,6,$V$41:$V$60,"Y") -> 0 | G17: =SUMIFS($P$41:$P$60,$R$41:$R$60,2024,$S$41:$S$60,7,$V$41:$V$60,"Y") -> 0 | H17: =SUMIFS($P$41:$P$60,$R$41:$R$60,2024,$S$41:$S$60,8,$V$41:$V$60,"Y") -> 26480.58 | I17: =SUMIFS($P$41:$P$60,$R$41:$R$60,2024,$S$41:$S$60,9,$V$41:$V$60,"Y") -> 0 | J17: =SUMIFS($P$41:$P$60,$R$41:$R$60,2024,$S$41:$S$60,10,$V$41:$V$60,"Y") -> 1386272 | K17: =SUMIFS($P$41:$P$60,$R$41:$R$60,2024,$S$41:$S$60,11,$V$41:$V$60,"Y") -> 0 | L17: =SUMIFS($P$41:$P$60,$R$41:$R$60,2024,$S$41:$S$60,12,$V$41:$V$60,"Y") -> 2626.46
A18: =SUMIFS($U$41:$U$60,$R$41:$R$60,2024,$S$41:$S$60,1,$V$41:$V$60,"Y") -> 0 | B18: =SUMIFS($U$41:$U$60,$R$41:$R$60,2024,$S$41:$S$60,2,$V$41:$V$60,"Y") -> 0 | C18: =SUMIFS($U$41:$U$60,$R$41:$R$60,2024,$S$41:$S$60,3,$V$41:$V$60,"Y") -> 0 | D18: =SUMIFS($U$41:$U$60,$R$41:$R$60,2024,$S$41:$S$60,4,$V$41:$V$60,"Y") -> 0 | E18: =SUMIFS($U$41:$U$60,$R$41:$R$60,2024,$S$41:$S$60,5,$V$41:$V$60,"Y") -> 0 | F18: =SUMIFS($U$41:$U$60,$R$41:$R$60,2024,$S$41:$S$60,6,$V$41:$V$60,"Y") -> 0 | G18: =SUMIFS($U$41:$U$60,$R$41:$R$60,2024,$S$41:$S$60,7,$V$41:$V$60,"Y") -> 0 | H18: =SUMIFS($U$41:$U$60,$R$41:$R$60,2024,$S$41:$S$60,8,$V$41:$V$60,"Y") -> 39720870 | I18: =SUMIFS($U$41:$U$60,$R$41:$R$60,2024,$S$41:$S$60,9,$V$41:$V$60,"Y") -> 0 | J18: =SUMIFS($U$41:$U$60,$R$41:$R$60,2024,$S$41:$S$60,10,$V$41:$V$60,"Y") -> 2.0642913e+08 | K18: =SUMIFS($U$41:$U$60,$R$41:$R$60,2024,$S$41:$S$60,11,$V$41:$V$60,"Y") -> 0 | L18: =SUMIFS($U$41:$U$60,$R$41:$R$60,2024,$S$41:$S$60,12,$V$41:$V$60,"Y") -> 0
A20: 2025 | B20: =SUM(A22:L22) -> 1276532.6 | C20: =SUM(A23:L23) -> 0
A21: 01 | B21: 02 | C21: 03 | D21: 04 | E21: 05 | F21: 06 | G21: 07 | H21: 08 | I21: 09 | J21: 10 | K21: 11 | L21: 12
A22: =SUMIFS($P$41:$P$60,$R$41:$R$60,2025,$S$41:$S$60,1,$V$41:$V$60,"Y") -> 2603.63 | B22: =SUMIFS($P$41:$P$60,$R$41:$R$60,2025,$S$41:$S$60,2,$V$41:$V$60,"Y") -> 3495.17 | C22: =SUMIFS($P$41:$P$60,$R$41:$R$60,2025,$S$41:$S$60,3,$V$41:$V$60,"Y") -> 28596.55 | D22: =SUMIFS($P$41:$P$60,$R$41:$R$60,2025,$S$41:$S$60,4,$V$41:$V$60,"Y") -> 6399.93 | E22: =SUMIFS($P$41:$P$60,$R$41:$R$60,2025,$S$41:$S$60,5,$V$41:$V$60,"Y") -> 22753.1 | F22: =SUMIFS($P$41:$P$60,$R$41:$R$60,2025,$S$41:$S$60,6,$V$41:$V$60,"Y") -> 31921.13 | G22: =SUMIFS($P$41:$P$92,$R$41:$R$92,2025,$S$41:$S$92,7,$V$41:$V$92,"Y") -> 280003.73 | H22: =SUMIFS($P$41:$P$92,$R$41:$R$92,2025,$S$41:$S$92,8,$V$41:$V$92,"Y") -> 86582.7 | I22: =SUMIFS($P$41:$P$60,$R$41:$R$60,2025,$S$41:$S$60,9,$V$41:$V$60,"Y") -> 0 | J22: =SUMIFS($P$41:$P$60,$R$41:$R$60,2025,$S$41:$S$60,10,$V$41:$V$60,"Y") -> 0 | K22: =SUMIFS($P$41:$P$60,$R$41:$R$60,2025,$S$41:$S$60,11,$V$41:$V$60,"Y") -> 253009.14 | L22: =SUMIFS($P$41:$P$92,$R$41:$R$92,2025,$S$41:$S$92,12,$V$41:$V$92,"Y") -> 561167.5
A23: =SUMIFS($U$41:$U$60,$R$41:$R$60,2025,$S$41:$S$60,1,$V$41:$V$60,"Y") -> 0 | B23: =SUMIFS($U$41:$U$60,$R$41:$R$60,2025,$S$41:$S$60,2,$V$41:$V$60,"Y") -> 0 | C23: =SUMIFS($U$41:$U$60,$R$41:$R$60,2025,$S$41:$S$60,3,$V$41:$V$60,"Y") -> 0 | D23: =SUMIFS($U$41:$U$60,$R$41:$R$60,2025,$S$41:$S$60,4,$V$41:$V$60,"Y") -> 0 | E23: =SUMIFS($U$41:$U$60,$R$41:$R$60,2025,$S$41:$S$60,5,$V$41:$V$60,"Y") -> 0 | F23: =SUMIFS($U$41:$U$60,$R$41:$R$60,2025,$S$41:$S$60,6,$V$41:$V$60,"Y") -> 0 | G23: =SUMIFS($U$41:$U$60,$R$41:$R$60,2025,$S$41:$S$60,7,$V$41:$V$60,"Y") -> 0 | H23: =SUMIFS($U$41:$U$60,$R$41:$R$60,2025,$S$41:$S$60,8,$V$41:$V$60,"Y") -> 0 | I23: =SUMIFS($U$41:$U$60,$R$41:$R$60,2025,$S$41:$S$60,9,$V$41:$V$60,"Y") -> 0 | J23: =SUMIFS($U$41:$U$60,$R$41:$R$60,2025,$S$41:$S$60,10,$V$41:$V$60,"Y") -> 0 | K23: =SUMIFS($U$41:$U$60,$R$41:$R$60,2025,$S$41:$S$60,11,$V$41:$V$60,"Y") -> 0 | L23: =SUMIFS($U$41:$U$60,$R$41:$R$60,2025,$S$41:$S$60,12,$V$41:$V$60,"Y") -> 0
A25: 2026 | B25: =SUM(A27:L27) -> 1254386.1 | C25: =SUM(A28:L28) -> 0
A26: 01 | B26: 02 | C26: 03 | D26: 04 | E26: 05 | F26: 06 | G26: 07 | H26: 08 | I26: 09 | J26: 10 | K26: 11 | L26: 12
A27: =SUMIFS($P$41:$P$67,$R$41:$R$67,2026,$S$41:$S$67,1,$V$41:$V$67,"Y") -> 429677.89 | B27: =SUMIFS($P$41:$P$67,$R$41:$R$67,2026,$S$41:$S$67,2,$V$41:$V$67,"Y") -> 0 | C27: =SUMIFS($P$41:$P$67,$R$41:$R$67,2026,$S$41:$S$67,3,$V$41:$V$67,"Y") -> 0 | D27: =SUMIFS($P$41:$P$86,$R$41:$R$86,2026,$S$41:$S$86,4,$V$41:$V$86,"Y") -> 253068.95 | E27: =SUMIFS($P$41:$P$86,$R$41:$R$86,2026,$S$41:$S$86,5,$V$41:$V$86,"Y") -> 112404.17 | F27: =SUMIFS($P$41:$P$86,$R$41:$R$86,2026,$S$41:$S$86,6,$V$41:$V$86,"Y") -> 325157.15 | G27: =SUMIFS($P$41:$P$86,$R$41:$R$86,2026,$S$41:$S$86,7,$V$41:$V$86,"Y") -> 134077.92 | H27: =SUMIFS($P$41:$P$86,$R$41:$R$86,2026,$S$41:$S$86,8,$V$41:$V$86,"Y") -> 0 | I27: =SUMIFS($P$41:$P$86,$R$41:$R$86,2026,$S$41:$S$86,9,$V$41:$V$86,"Y") -> 0 | J27: =SUMIFS($P$41:$P$86,$R$41:$R$86,2026,$S$41:$S$86,10,$V$41:$V$86,"Y") -> 0 | K27: =SUMIFS($P$41:$P$70,$R$41:$R$70,2026,$S$41:$S$70,11,$V$41:$V$70,"Y") -> 0 | L27: =SUMIFS($P$41:$P$70,$R$41:$R$70,2026,$S$41:$S$70,12,$V$41:$V$70,"Y") -> 0
A28: =SUMIFS($U$41:$U$60,$R$41:$R$60,2026,$S$41:$S$60,1,$V$41:$V$60,"Y") -> 0 | B28: =SUMIFS($U$41:$U$60,$R$41:$R$60,2026,$S$41:$S$60,2,$V$41:$V$60,"Y") -> 0 | C28: =SUMIFS($U$41:$U$60,$R$41:$R$60,2026,$S$41:$S$60,3,$V$41:$V$60,"Y") -> 0 | D28: =SUMIFS($U$41:$U$60,$R$41:$R$60,2026,$S$41:$S$60,4,$V$41:$V$60,"Y") -> 0 | E28: =SUMIFS($U$41:$U$60,$R$41:$R$60,2026,$S$41:$S$60,5,$V$41:$V$60,"Y") -> 0 | F28: =SUMIFS($U$41:$U$60,$R$41:$R$60,2026,$S$41:$S$60,6,$V$41:$V$60,"Y") -> 0 | G28: =SUMIFS($U$41:$U$60,$R$41:$R$60,2026,$S$41:$S$60,7,$V$41:$V$60,"Y") -> 0 | H28: =SUMIFS($U$41:$U$60,$R$41:$R$60,2026,$S$41:$S$60,8,$V$41:$V$60,"Y") -> 0 | I28: =SUMIFS($U$41:$U$60,$R$41:$R$60,2026,$S$41:$S$60,9,$V$41:$V$60,"Y") -> 0 | J28: =SUMIFS($U$41:$U$60,$R$41:$R$60,2026,$S$41:$S$60,10,$V$41:$V$60,"Y") -> 0 | K28: =SUMIFS($U$41:$U$60,$R$41:$R$60,2026,$S$41:$S$60,11,$V$41:$V$60,"Y") -> 0 | L28: =SUMIFS($U$41:$U$60,$R$41:$R$60,2026,$S$41:$S$60,12,$V$41:$V$60,"Y") -> 0
A30: 2027 | B30: =SUM(A32:L32) -> 0 | C30: =SUM(A33:L33) -> 0
A31: 01 | B31: 02 | C31: 03 | D31: 04 | E31: 05 | F31: 06 | G31: 07 | H31: 08 | I31: 09 | J31: 10 | K31: 11 | L31: 12
A32: =SUMIFS($P$41:$P$60,$R$41:$R$60,2027,$S$41:$S$60,1,$V$41:$V$60,"Y") -> 0 | B32: =SUMIFS($P$41:$P$60,$R$41:$R$60,2027,$S$41:$S$60,2,$V$41:$V$60,"Y") -> 0 | C32: =SUMIFS($P$41:$P$60,$R$41:$R$60,2027,$S$41:$S$60,3,$V$41:$V$60,"Y") -> 0 | D32: =SUMIFS($P$41:$P$60,$R$41:$R$60,2027,$S$41:$S$60,4,$V$41:$V$60,"Y") -> 0 | E32: =SUMIFS($P$41:$P$60,$R$41:$R$60,2027,$S$41:$S$60,5,$V$41:$V$60,"Y") -> 0 | F32: =SUMIFS($P$41:$P$60,$R$41:$R$60,2027,$S$41:$S$60,6,$V$41:$V$60,"Y") -> 0 | G32: =SUMIFS($P$41:$P$60,$R$41:$R$60,2027,$S$41:$S$60,7,$V$41:$V$60,"Y") -> 0 | H32: =SUMIFS($P$41:$P$60,$R$41:$R$60,2027,$S$41:$S$60,8,$V$41:$V$60,"Y") -> 0 | I32: =SUMIFS($P$41:$P$60,$R$41:$R$60,2027,$S$41:$S$60,9,$V$41:$V$60,"Y") -> 0 | J32: =SUMIFS($P$41:$P$60,$R$41:$R$60,2027,$S$41:$S$60,10,$V$41:$V$60,"Y") -> 0 | K32: =SUMIFS($P$41:$P$60,$R$41:$R$60,2027,$S$41:$S$60,11,$V$41:$V$60,"Y") -> 0 | L32: =SUMIFS($P$41:$P$60,$R$41:$R$60,2027,$S$41:$S$60,12,$V$41:$V$60,"Y") -> 0
A33: =SUMIFS($U$41:$U$60,$R$41:$R$60,2027,$S$41:$S$60,1,$V$41:$V$60,"Y") -> 0 | B33: =SUMIFS($U$41:$U$60,$R$41:$R$60,2027,$S$41:$S$60,2,$V$41:$V$60,"Y") -> 0 | C33: =SUMIFS($U$41:$U$60,$R$41:$R$60,2027,$S$41:$S$60,3,$V$41:$V$60,"Y") -> 0 | D33: =SUMIFS($U$41:$U$60,$R$41:$R$60,2027,$S$41:$S$60,4,$V$41:$V$60,"Y") -> 0 | E33: =SUMIFS($U$41:$U$60,$R$41:$R$60,2027,$S$41:$S$60,5,$V$41:$V$60,"Y") -> 0 | F33: =SUMIFS($U$41:$U$60,$R$41:$R$60,2027,$S$41:$S$60,6,$V$41:$V$60,"Y") -> 0 | G33: =SUMIFS($U$41:$U$60,$R$41:$R$60,2027,$S$41:$S$60,7,$V$41:$V$60,"Y") -> 0 | H33: =SUMIFS($U$41:$U$60,$R$41:$R$60,2027,$S$41:$S$60,8,$V$41:$V$60,"Y") -> 0 | I33: =SUMIFS($U$41:$U$60,$R$41:$R$60,2027,$S$41:$S$60,9,$V$41:$V$60,"Y") -> 0 | J33: =SUMIFS($U$41:$U$60,$R$41:$R$60,2027,$S$41:$S$60,10,$V$41:$V$60,"Y") -> 0 | K33: =SUMIFS($U$41:$U$60,$R$41:$R$60,2027,$S$41:$S$60,11,$V$41:$V$60,"Y") -> 0 | L33: =SUMIFS($U$41:$U$60,$R$41:$R$60,2027,$S$41:$S$60,12,$V$41:$V$60,"Y") -> 0
A35: 3. PTC details
A36: Budget | B36: =1248213+24756.78+137619.42+26480.58 -> 1437069.8 | C36: 26740 | D36: 267560 | E36: 421115.32 | F36: 498.6 | G36: 171 | H36: 5544 | I36: 24717 | J36: - | K36: 39.78 | L36: 556302 | M36: 62192 | N36: 3467289 | O36: 4367720
A37: Invoiced | B37: =SUM(B41:B77) -> 3946297.7 | C37: =SUM(C41:C60) -> 0 | D37: =SUM(D41:D60) -> 0 | E37: =SUM(E41:E60) -> 0 | F37: =SUM(F41:F60) -> 0 | G37: =SUM(G41:G60) -> 0 | H37: =SUM(H41:H60) -> 0 | I37: =SUM(I41:I60) -> 0 | J37: =SUM(J41:J60) -> 0 | ... O37: =SUM(O41:O60) -> 0
A38: Remaining | B38: =B36-B37 -> -2509227.9 | C38: =C36-C37 -> 26740 | D38: =D36-D37 -> 267560 | E38: =E36-E37 -> 421115.32 | F38: =F36-F37 -> 498.6 | G38: =G36-G37 -> 171 | H38: =H36-H37 -> 5544 | I38: =I36-I37 -> 24717 | ... O38: =O36-O37 -> 4367720
A39: Remaining (%) | C39: =C38/C36 -> 1 | D39: =D38/D36 -> 1 | E39: =E38/E36 -> 1 | F39: =F38/F36 -> 1 | G39: =G38/G36 -> 1 | H39: =H38/H36 -> 1 | I39: =I38/I36 -> 1 | J39: =J38/J36 -> #VALUE! | ... O39: =O38/O36 -> 1
A40: Invoice # | B40: Deposit (Budget 미포함) | C40: Office Supplies | D40: Monitoring Travel | E40: Regulatory/IRB/EC fees | F40: Document Indexing, QC and File Review | G40: Printing | H40: Teleconferences | I40: Miscellaneous Administrative Overhead | J40: Informed Consent Form | K40: DocuSign | L40: Clario | M40: Investigator Meetings Logistics | N40: Investigator Payments (North America) | O40: Investigator Payments (Asia Pacific) | P40: Invoiced Amount($) | Q40: Invoiced Date | R40: Paid Year | S40: Paid Month | T40: Paid Date | U40: Paid Amount(₩) | V40: Paid (Y) | W40: 지출결의 #
A41: SGP-030212 | B41: 26480.58 | P41: =SUM(B41:O41) -> 26480.58 | Q41: 45495 | R41: 2024 | S41: 8 | T41: 45512 | U41: 39720870 | V41: Y | W41: CD24-170
A42: SGP-030531 | B42: 137619.42 | P42: =SUM(B42:O42) -> 137619.42 | Q42: 45562 | R42: 2024 | S42: 10 | T42: 45575 | U42: 2.0642913e+08 | V42: Y | W42: CD24-220
A43: SGP-030532 | B43: 1248213 | P43: =SUM(B43:O43) -> 1248213 | Q43: 45562 | R43: 2024 | S43: 10 | T43: 45575 | V43: Y | W43: CD24-220
A44: SGP-030621 | B44: 439.55 | P44: =SUM(B44:O44) -> 439.55 | Q44: 45580 | R44: 2024 | S44: 10 | T44: 45589 | V44: Y | W44: CD24-225
A45: SGP-030789 | B45: 2626.46 | P45: =SUM(B45:O45) -> 2626.46 | Q45: 45617 | R45: 2024 | S45: 12 | T45: 45631 | V45: Y | W45: CD24-277
A46: SGP-030941 | B46: 2603.63 | P46: =SUM(B46:O46) -> 2603.63 | Q46: 45652 | R46: 2025 | S46: 1 | T46: 45659 | V46: Y | W46: CD24-289
A47: SGP-031090 | B47: 3495.17 | P47: =SUM(B47:O47) -> 3495.17 | Q47: 45699 | R47: 2025 | S47: 2 | T47: 45708 | V47: Y | W47: CD25-034
...

Sheet 2. Syneos
A1: 1. CRO:Syneos
B2: Contract Number: | D2: Version & date:
A4: Protocol No: TTK-CS-101 | D4: Updated on:
A6: 1. Total Payment Status
A7: Category | B7: $ | C7: %
A8: Budget
A9: Paid | B9: =B14+B19+B24+B29+B34 -> 0 | C9: =B9/B8 -> #DIV/0!
A10: Remaining | B10: =B8-B9 -> 0 | C10: =B10/B8 -> #DIV/0!
A12: 2.Yearly and Monthly Payment
B13: USD | C13: KRW
A14: 2023 | B14: =SUM(A16:L16) -> 0 | C14: =SUM(A17:L17) -> 0
A15: 01 | B15: 02 | C15: 03 | D15: 04 | E15: 05 | F15: 06 | G15: 07 | H15: 08 | I15: 09 | J15: 10 | K15: 11 | L15: 12
A16: =SUMIFS($C$41:$C$61,$F$41:$F$61,2024,$G$41:$G$61,1,$J$41:$J$61,"Y") -> 0 | B16: =SUMIFS($C$41:$C$61,$F$41:$F$61,2024,$G$41:$G$61,2,$J$41:$J$61,"Y") -> 0 | C16: =SUMIFS($C$41:$C$61,$F$41:$F$61,2024,$G$41:$G$61,3,$J$41:$J$61,"Y") -> 0 | D16: =SUMIFS($C$41:$C$61,$F$41:$F$61,2024,$G$41:$G$61,4,$J$41:$J$61,"Y") -> 0 | E16: =SUMIFS($C$41:$C$61,$F$41:$F$61,2024,$G$41:$G$61,5,$J$41:$J$61,"Y") -> 0 | F16: =SUMIFS($C$41:$C$61,$F$41:$F$61,2024,$G$41:$G$61,6,$J$41:$J$61,"Y") -> 0 | G16: =SUMIFS($C$41:$C$61,$F$41:$F$61,2024,$G$41:$G$61,7,$J$41:$J$61,"Y") -> 0 | H16: =SUMIFS($C$41:$C$61,$F$41:$F$61,2024,$G$41:$G$61,8,$J$41:$J$61,"Y") -> 0 | I16: =SUMIFS($C$41:$C$61,$F$41:$F$61,2024,$G$41:$G$61,9,$J$41:$J$61,"Y") -> 0 | J16: =SUMIFS($C$41:$C$61,$F$41:$F$61,2024,$G$41:$G$61,10,$J$41:$J$61,"Y") -> 0 | K16: =SUMIFS($C$41:$C$61,$F$41:$F$61,2024,$G$41:$G$61,11,$J$41:$J$61,"Y") -> 0 | L16: =SUMIFS($C$41:$C$61,$F$41:$F$61,2024,$G$41:$G$61,12,$J$41:$J$61,"Y") -> 0
A17: =SUMIFS($I$41:$I$61,$F$41:$F$61,2024,$G$41:$G$61,1,$J$41:$J$61,"Y") -> 0 | B17: =SUMIFS($I$41:$I$61,$F$41:$F$61,2024,$G$41:$G$61,2,$J$41:$J$61,"Y") -> 0 | C17: =SUMIFS($I$41:$I$61,$F$41:$F$61,2024,$G$41:$G$61,3,$J$41:$J$61,"Y") -> 0 | D17: =SUMIFS($I$41:$I$61,$F$41:$F$61,2024,$G$41:$G$61,4,$J$41:$J$61,"Y") -> 0 | E17: =SUMIFS($I$41:$I$61,$F$41:$F$61,2024,$G$41:$G$61,5,$J$41:$J$61,"Y") -> 0 | F17: =SUMIFS($I$41:$I$61,$F$41:$F$61,2024,$G$41:$G$61,6,$J$41:$J$61,"Y") -> 0 | G17: =SUMIFS($I$41:$I$61,$F$41:$F$61,2024,$G$41:$G$61,7,$J$41:$J$61,"Y") -> 0 | H17: =SUMIFS($I$41:$I$61,$F$41:$F$61,2024,$G$41:$G$61,8,$J$41:$J$61,"Y") -> 0 | I17: =SUMIFS($I$41:$I$61,$F$41:$F$61,2024,$G$41:$G$61,9,$J$41:$J$61,"Y") -> 0 | J17: =SUMIFS($I$41:$I$61,$F$41:$F$61,2024,$G$41:$G$61,10,$J$41:$J$61,"Y") -> 0 | K17: =SUMIFS($I$41:$I$61,$F$41:$F$61,2024,$G$41:$G$61,11,$J$41:$J$61,"Y") -> 0 | L17: =SUMIFS($I$41:$I$61,$F$41:$F$61,2024,$G$41:$G$61,12,$J$41:$J$61,"Y") -> 0
A19: 2024 | B19: =SUM(A21:L21) -> 0 | C19: =SUM(A22:L22) -> 0
A20: 01 | B20: 02 | C20: 03 | D20: 04 | E20: 05 | F20: 06 | G20: 07 | H20: 08 | I20: 09 | J20: 10 | K20: 11 | L20: 12
A21: =SUMIFS($C$41:$C$61,$F$41:$F$61,2024,$G$41:$G$61,1,$J$41:$J$61,"Y") -> 0 | B21: =SUMIFS($C$41:$C$61,$F$41:$F$61,2024,$G$41:$G$61,2,$J$41:$J$61,"Y") -> 0 | C21: =SUMIFS($C$41:$C$61,$F$41:$F$61,2024,$G$41:$G$61,3,$J$41:$J$61,"Y") -> 0 | D21: =SUMIFS($C$41:$C$61,$F$41:$F$61,2024,$G$41:$G$61,4,$J$41:$J$61,"Y") -> 0 | E21: =SUMIFS($C$41:$C$61,$F$41:$F$61,2024,$G$41:$G$61,5,$J$41:$J$61,"Y") -> 0 | F21: =SUMIFS($C$41:$C$61,$F$41:$F$61,2024,$G$41:$G$61,6,$J$41:$J$61,"Y") -> 0 | G21: =SUMIFS($C$41:$C$61,$F$41:$F$61,2024,$G$41:$G$61,7,$J$41:$J$61,"Y") -> 0 | H21: =SUMIFS($C$41:$C$61,$F$41:$F$61,2024,$G$41:$G$61,8,$J$41:$J$61,"Y") -> 0 | I21: =SUMIFS($C$41:$C$61,$F$41:$F$61,2024,$G$41:$G$61,9,$J$41:$J$61,"Y") -> 0 | J21: =SUMIFS($C$41:$C$61,$F$41:$F$61,2024,$G$41:$G$61,10,$J$41:$J$61,"Y") -> 0 | K21: =SUMIFS($C$41:$C$61,$F$41:$F$61,2024,$G$41:$G$61,11,$J$41:$J$61,"Y") -> 0 | L21: =SUMIFS($C$41:$C$61,$F$41:$F$61,2024,$G$41:$G$61,12,$J$41:$J$61,"Y") -> 0
A22: =SUMIFS($I$41:$I$61,$F$41:$F$61,2024,$G$41:$G$61,1,$J$41:$J$61,"Y") -> 0 | B22: =SUMIFS($I$41:$I$61,$F$41:$F$61,2024,$G$41:$G$61,2,$J$41:$J$61,"Y") -> 0 | C22: =SUMIFS($I$41:$I$61,$F$41:$F$61,2024,$G$41:$G$61,3,$J$41:$J$61,"Y") -> 0 | D22: =SUMIFS($I$41:$I$61,$F$41:$F$61,2024,$G$41:$G$61,4,$J$41:$J$61,"Y") -> 0 | E22: =SUMIFS($I$41:$I$61,$F$41:$F$61,2024,$G$41:$G$61,5,$J$41:$J$61,"Y") -> 0 | F22: =SUMIFS($I$41:$I$61,$F$41:$F$61,2024,$G$41:$G$61,6,$J$41:$J$61,"Y") -> 0 | G22: =SUMIFS($I$41:$I$61,$F$41:$F$61,2024,$G$41:$G$61,7,$J$41:$J$61,"Y") -> 0 | H22: =SUMIFS($I$41:$I$61,$F$41:$F$61,2024,$G$41:$G$61,8,$J$41:$J$61,"Y") -> 0 | I22: =SUMIFS($I$41:$I$61,$F$41:$F$61,2024,$G$41:$G$61,9,$J$41:$J$61,"Y") -> 0 | J22: =SUMIFS($I$41:$I$61,$F$41:$F$61,2024,$G$41:$G$61,10,$J$41:$J$61,"Y") -> 0 | K22: =SUMIFS($I$41:$I$61,$F$41:$F$61,2024,$G$41:$G$61,11,$J$41:$J$61,"Y") -> 0 | L22: =SUMIFS($I$41:$I$61,$F$41:$F$61,2024,$G$41:$G$61,12,$J$41:$J$61,"Y") -> 0
A24: 2025 | B24: =SUM(A26:L26) -> 0 | C24: =SUM(A27:L27) -> 0
A25: 01 | B25: 02 | C25: 03 | D25: 04 | E25: 05 | F25: 06 | G25: 07 | H25: 08 | I25: 09 | J25: 10 | K25: 11 | L25: 12
A26: =SUMIFS($C$41:$C$61,$F$41:$F$61,2025,$G$41:$G$61,1,$J$41:$J$61,"Y") -> 0 | B26: =SUMIFS($C$41:$C$61,$F$41:$F$61,2025,$G$41:$G$61,2,$J$41:$J$61,"Y") -> 0 | C26: =SUMIFS($C$41:$C$61,$F$41:$F$61,2025,$G$41:$G$61,3,$J$41:$J$61,"Y") -> 0 | D26: =SUMIFS($C$41:$C$61,$F$41:$F$61,2025,$G$41:$G$61,4,$J$41:$J$61,"Y") -> 0 | E26: =SUMIFS($C$41:$C$61,$F$41:$F$61,2025,$G$41:$G$61,5,$J$41:$J$61,"Y") -> 0 | F26: =SUMIFS($C$41:$C$61,$F$41:$F$61,2025,$G$41:$G$61,6,$J$41:$J$61,"Y") -> 0 | G26: =SUMIFS($C$41:$C$61,$F$41:$F$61,2025,$G$41:$G$61,7,$J$41:$J$61,"Y") -> 0 | H26: =SUMIFS($C$41:$C$61,$F$41:$F$61,2025,$G$41:$G$61,8,$J$41:$J$61,"Y") -> 0 | I26: =SUMIFS($C$41:$C$61,$F$41:$F$61,2025,$G$41:$G$61,9,$J$41:$J$61,"Y") -> 0 | J26: =SUMIFS($C$41:$C$61,$F$41:$F$61,2025,$G$41:$G$61,10,$J$41:$J$61,"Y") -> 0 | K26: =SUMIFS($C$41:$C$61,$F$41:$F$61,2025,$G$41:$G$61,11,$J$41:$J$61,"Y") -> 0 | L26: =SUMIFS($C$41:$C$61,$F$41:$F$61,2025,$G$41:$G$61,12,$J$41:$J$61,"Y") -> 0
A27: =SUMIFS($I$41:$I$61,$F$41:$F$61,2025,$G$41:$G$61,1,$J$41:$J$61,"Y") -> 0 | B27: =SUMIFS($I$41:$I$61,$F$41:$F$61,2025,$G$41:$G$61,2,$J$41:$J$61,"Y") -> 0 | C27: =SUMIFS($I$41:$I$61,$F$41:$F$61,2025,$G$41:$G$61,3,$J$41:$J$61,"Y") -> 0 | D27: =SUMIFS($I$41:$I$61,$F$41:$F$61,2025,$G$41:$G$61,4,$J$41:$J$61,"Y") -> 0 | E27: =SUMIFS($I$41:$I$61,$F$41:$F$61,2025,$G$41:$G$61,5,$J$41:$J$61,"Y") -> 0 | F27: =SUMIFS($I$41:$I$61,$F$41:$F$61,2025,$G$41:$G$61,6,$J$41:$J$61,"Y") -> 0 | G27: =SUMIFS($I$41:$I$61,$F$41:$F$61,2025,$G$41:$G$61,7,$J$41:$J$61,"Y") -> 0 | H27: =SUMIFS($I$41:$I$61,$F$41:$F$61,2025,$G$41:$G$61,8,$J$41:$J$61,"Y") -> 0 | I27: =SUMIFS($I$41:$I$61,$F$41:$F$61,2025,$G$41:$G$61,9,$J$41:$J$61,"Y") -> 0 | J27: =SUMIFS($I$41:$I$61,$F$41:$F$61,2025,$G$41:$G$61,10,$J$41:$J$61,"Y") -> 0 | K27: =SUMIFS($I$41:$I$61,$F$41:$F$61,2025,$G$41:$G$61,11,$J$41:$J$61,"Y") -> 0 | L27: =SUMIFS($I$41:$I$61,$F$41:$F$61,2025,$G$41:$G$61,12,$J$41:$J$61,"Y") -> 0
A29: 2026 | B29: =SUM(A31:L31) -> 0 | C29: =SUM(A32:L32) -> 0
A30: 01 | B30: 02 | C30: 03 | D30: 04 | E30: 05 | F30: 06 | G30: 07 | H30: 08 | I30: 09 | J30: 10 | K30: 11 | L30: 12
A31: =SUMIFS($C$41:$C$61,$F$41:$F$61,2026,$G$41:$G$61,1,$J$41:$J$61,"Y") -> 0 | B31: =SUMIFS($C$41:$C$61,$F$41:$F$61,2026,$G$41:$G$61,2,$J$41:$J$61,"Y") -> 0 | C31: =SUMIFS($C$41:$C$61,$F$41:$F$61,2026,$G$41:$G$61,3,$J$41:$J$61,"Y") -> 0 | D31: =SUMIFS($C$41:$C$61,$F$41:$F$61,2026,$G$41:$G$61,4,$J$41:$J$61,"Y") -> 0 | E31: =SUMIFS($C$41:$C$61,$F$41:$F$61,2026,$G$41:$G$61,5,$J$41:$J$61,"Y") -> 0 | F31: =SUMIFS($C$41:$C$61,$F$41:$F$61,2026,$G$41:$G$61,6,$J$41:$J$61,"Y") -> 0 | G31: =SUMIFS($C$41:$C$61,$F$41:$F$61,2026,$G$41:$G$61,7,$J$41:$J$61,"Y") -> 0 | H31: =SUMIFS($C$41:$C$61,$F$41:$F$61,2026,$G$41:$G$61,8,$J$41:$J$61,"Y") -> 0 | I31: =SUMIFS($C$41:$C$61,$F$41:$F$61,2026,$G$41:$G$61,9,$J$41:$J$61,"Y") -> 0 | J31: =SUMIFS($C$41:$C$61,$F$41:$F$61,2026,$G$41:$G$61,10,$J$41:$J$61,"Y") -> 0 | K31: =SUMIFS($C$41:$C$61,$F$41:$F$61,2026,$G$41:$G$61,11,$J$41:$J$61,"Y") -> 0 | L31: =SUMIFS($C$41:$C$61,$F$41:$F$61,2026,$G$41:$G$61,12,$J$41:$J$61,"Y") -> 0
A32: =SUMIFS($I$41:$I$61,$F$41:$F$61,2026,$G$41:$G$61,1,$J$41:$J$61,"Y") -> 0 | B32: =SUMIFS($I$41:$I$61,$F$41:$F$61,2026,$G$41:$G$61,2,$J$41:$J$61,"Y") -> 0 | C32: =SUMIFS($I$41:$I$61,$F$41:$F$61,2026,$G$41:$G$61,3,$J$41:$J$61,"Y") -> 0 | D32: =SUMIFS($I$41:$I$61,$F$41:$F$61,2026,$G$41:$G$61,4,$J$41:$J$61,"Y") -> 0 | E32: =SUMIFS($I$41:$I$61,$F$41:$F$61,2026,$G$41:$G$61,5,$J$41:$J$61,"Y") -> 0 | F32: =SUMIFS($I$41:$I$61,$F$41:$F$61,2026,$G$41:$G$61,6,$J$41:$J$61,"Y") -> 0 | G32: =SUMIFS($I$41:$I$61,$F$41:$F$61,2026,$G$41:$G$61,7,$J$41:$J$61,"Y") -> 0 | H32: =SUMIFS($I$41:$I$61,$F$41:$F$61,2026,$G$41:$G$61,8,$J$41:$J$61,"Y") -> 0 | I32: =SUMIFS($I$41:$I$61,$F$41:$F$61,2026,$G$41:$G$61,9,$J$41:$J$61,"Y") -> 0 | J32: =SUMIFS($I$41:$I$61,$F$41:$F$61,2026,$G$41:$G$61,10,$J$41:$J$61,"Y") -> 0 | K32: =SUMIFS($I$41:$I$61,$F$41:$F$61,2026,$G$41:$G$61,11,$J$41:$J$61,"Y") -> 0 | L32: =SUMIFS($I$41:$I$61,$F$41:$F$61,2026,$G$41:$G$61,12,$J$41:$J$61,"Y") -> 0
A34: 2027 | B34: =SUM(A36:L36) -> 0 | C34: =SUM(A37:L37) -> 0
A35: 01 | B35: 02 | C35: 03 | D35: 04 | E35: 05 | F35: 06 | G35: 07 | H35: 08 | I35: 09 | J35: 10 | K35: 11 | L35: 12
